Workbook

Sheet SAISIE
A1: Date | B1: DJ | C1: RTR | D1: Bâtiment | E1: =LISTES!$A$2 | F1: =LISTES!$A$3 | G1: =LISTES!$A$4 | H1: =LISTES!$A$5 | I1: =LISTES!$A$6 | J1: =LISTES!$A$7 | K1: =LISTES!$A$8 | L1: =LISTES!$A$9 | M1: =LISTES!$A$10 | N1: =LISTES!$A$11 | O1: Commentaire
A2: 46072 | B2: AM | C2: RTR-1 | D2: BAN7 | E2: 0.002
A3: =IF(B3=LISTES!$C$2,A2+1,A2) | B3: =IF(B2=LISTES!$C$2,LISTES!$C$3,LISTES!$C$2)
A4: =IF(B4=LISTES!$C$2,A3+1,A3) | B4: =IF(B3=LISTES!$C$2,LISTES!$C$3,LISTES!$C$2)
A5: =IF(B5=LISTES!$C$2,A4+1,A4) | B5: =IF(B4=LISTES!$C$2,LISTES!$C$3,LISTES!$C$2)
A6: =IF(B6=LISTES!$C$2,A5+1,A5) | B6: =IF(B5=LISTES!$C$2,LISTES!$C$3,LISTES!$C$2)
A7: =IF(B7=LISTES!$C$2,A6+1,A6) | B7: =IF(B6=LISTES!$C$2,LISTES!$C$3,LISTES!$C$2)
A8: =IF(B8=LISTES!$C$2,A7+1,A7) | B8: =IF(B7=LISTES!$C$2,LISTES!$C$3,LISTES!$C$2)
A9: =IF(B9=LISTES!$C$2,A8+1,A8) | B9: =IF(B8=LISTES!$C$2,LISTES!$C$3,LISTES!$C$2)
A10: =IF(B10=LISTES!$C$2,A9+1,A9) | B10: =IF(B9=LISTES!$C$2,LISTES!$C$3,LISTES!$C$2)
A11: =IF(B11=LISTES!$C$2,A10+1,A10) | B11: =IF(B10=LISTES!$C$2,LISTES!$C$3,LISTES!$C$2)
A12: =IF(B12=LISTES!$C$2,A11+1,A11) | B12: =IF(B11=LISTES!$C$2,LISTES!$C$3,LISTES!$C$2)
A13: =IF(B13=LISTES!$C$2,A12+1,A12) | B13: =IF(B12=LISTES!$C$2,LISTES!$C$3,LISTES!$C$2)
A14: =IF(B14=LISTES!$C$2,A13+1,A13) | B14: =IF(B13=LISTES!$C$2,LISTES!$C$3,LISTES!$C$2)
... A501: =IF(B501=LISTES!$C$2,A500+1,A500) | B501: =IF(B500=LISTES!$C$2,LISTES!$C$3,LISTES!$C$2)

Sheet SUIVI_RTR
A1: ▸ RTR CLASSIQUES
A2: RTR | B2: N° IZ | C2: Type | D2: Tranche | E2: Local | F2: Prévu (mSv) | G2: Consommé (mSv) | H2: Reste (mSv) | I2: % consommé
A3: =LISTES!$E$2 | B3: 91528925-1 | C3: Classique | D3: 7 | E3: - | F3: 1.716 | G3: =IF(LISTES!$E$2="",0,SUMIFS(SAISIE!$E$2:$E$501,SAISIE!$C$2:$C$501,LISTES!$E$2)+SUMIFS(SAISIE!$F$2:$F$501,SAISIE!$C$2:$C$501,LISTES!$E$2)+SUMIFS(SAISIE!$G$2:$G$501,SAISIE!$C$2:$C$501,LISTES!$E$2)+SUMIFS(SAISIE!$H$2:$H$501,SAISIE!$C$2:$C$501,LISTES!$E$2)+SUMIFS(SAISIE!$I$2:$I$501,SAISIE!$C$2:$C$501,LISTES!$E$2)+SUMIFS(SAISIE!$J$2:$J$501,SAISIE!$C$2:$C$501,LISTES!$E$2)+SUMIFS(SAISIE!$K$2:$K$501,SAISIE!$C$2:$C$501,LISTES!$E$2)+SUMIFS(SAISIE!$L$2:$L$501,SAISIE!$C$2:$C$501,LISTES!$E$2)+SUMIFS(SAISIE!$M$2:$M$501,SAISIE!$C$2:$C$501,LISTES!$E$2)+SUMIFS(SAISIE!$N$2:$N$501,SAISIE!$C$2:$C$501,LISTES!$E$2)) | H3: =IFERROR(IF(F3=0,"",F3-G3),"") | I3: =IFERROR(IF(F3=0,"",G3/F3),"")
A4: =LISTES!$E$3 | G4: =IF(LISTES!$E$3="",0,SUMIFS(SAISIE!$E$2:$E$501,SAISIE!$C$2:$C$501,LISTES!$E$3)+SUMIFS(SAISIE!$F$2:$F$501,SAISIE!$C$2:$C$501,LISTES!$E$3)+SUMIFS(SAISIE!$G$2:$G$501,SAISIE!$C$2:$C$501,LISTES!$E$3)+SUMIFS(SAISIE!$H$2:$H$501,SAISIE!$C$2:$C$501,LISTES!$E$3)+SUMIFS(SAISIE!$I$2:$I$501,SAISIE!$C$2:$C$501,LISTES!$E$3)+SUMIFS(SAISIE!$J$2:$J$501,SAISIE!$C$2:$C$501,LISTES!$E$3)+SUMIFS(SAISIE!$K$2:$K$501,SAISIE!$C$2:$C$501,LISTES!$E$3)+SUMIFS(SAISIE!$L$2:$L$501,SAISIE!$C$2:$C$501,LISTES!$E$3)+SUMIFS(SAISIE!$M$2:$M$501,SAISIE!$C$2:$C$501,LISTES!$E$3)+SUMIFS(SAISIE!$N$2:$N$501,SAISIE!$C$2:$C$501,LISTES!$E$3)) | H4: =IFERROR(IF(F4=0,"",F4-G4),"") | I4: =IFERROR(IF(F4=0,"",G4/F4),"")
A5: =LISTES!$E$4 | G5: =IF(LISTES!$E$4="",0,SUMIFS(SAISIE!$E$2:$E$501,SAISIE!$C$2:$C$501,LISTES!$E$4)+SUMIFS(SAISIE!$F$2:$F$501,SAISIE!$C$2:$C$501,LISTES!$E$4)+SUMIFS(SAISIE!$G$2:$G$501,SAISIE!$C$2:$C$501,LISTES!$E$4)+SUMIFS(SAISIE!$H$2:$H$501,SAISIE!$C$2:$C$501,LISTES!$E$4)+SUMIFS(SAISIE!$I$2:$I$501,SAISIE!$C$2:$C$501,LISTES!$E$4)+SUMIFS(SAISIE!$J$2:$J$501,SAISIE!$C$2:$C$501,LISTES!$E$4)+SUMIFS(SAISIE!$K$2:$K$501,SAISIE!$C$2:$C$501,LISTES!$E$4)+SUMIFS(SAISIE!$L$2:$L$501,SAISIE!$C$2:$C$501,LISTES!$E$4)+SUMIFS(SAISIE!$M$2:$M$501,SAISIE!$C$2:$C$501,LISTES!$E$4)+SUMIFS(SAISIE!$N$2:$N$501,SAISIE!$C$2:$C$501,LISTES!$E$4)) | H5: =IFERROR(IF(F5=0,"",F5-G5),"") | I5: =IFERROR(IF(F5=0,"",G5/F5),"")
A6: =LISTES!$E$5 | G6: =IF(LISTES!$E$5="",0,SUMIFS(SAISIE!$E$2:$E$501,SAISIE!$C$2:$C$501,LISTES!$E$5)+SUMIFS(SAISIE!$F$2:$F$501,SAISIE!$C$2:$C$501,LISTES!$E$5)+SUMIFS(SAISIE!$G$2:$G$501,SAISIE!$C$2:$C$501,LISTES!$E$5)+SUMIFS(SAISIE!$H$2:$H$501,SAISIE!$C$2:$C$501,LISTES!$E$5)+SUMIFS(SAISIE!$I$2:$I$501,SAISIE!$C$2:$C$501,LISTES!$E$5)+SUMIFS(SAISIE!$J$2:$J$501,SAISIE!$C$2:$C$501,LISTES!$E$5)+SUMIFS(SAISIE!$K$2:$K$501,SAISIE!$C$2:$C$501,LISTES!$E$5)+SUMIFS(SAISIE!$L$2:$L$501,SAISIE!$C$2:$C$501,LISTES!$E$5)+SUMIFS(SAISIE!$M$2:$M$501,SAISIE!$C$2:$C$501,LISTES!$E$5)+SUMIFS(SAISIE!$N$2:$N$501,SAISIE!$C$2:$C$501,LISTES!$E$5)) | H6: =IFERROR(IF(F6=0,"",F6-G6),"") | I6: =IFERROR(IF(F6=0,"",G6/F6),"")
A7: =LISTES!$E$6 | G7: =IF(LISTES!$E$6="",0,SUMIFS(SAISIE!$E$2:$E$501,SAISIE!$C$2:$C$501,LISTES!$E$6)+SUMIFS(SAISIE!$F$2:$F$501,SAISIE!$C$2:$C$501,LISTES!$E$6)+SUMIFS(SAISIE!$G$2:$G$501,SAISIE!$C$2:$C$501,LISTES!$E$6)+SUMIFS(SAISIE!$H$2:$H$501,SAISIE!$C$2:$C$501,LISTES!$E$6)+SUMIFS(SAISIE!$I$2:$I$501,SAISIE!$C$2:$C$501,LISTES!$E$6)+SUMIFS(SAISIE!$J$2:$J$501,SAISIE!$C$2:$C$501,LISTES!$E$6)+SUMIFS(SAISIE!$K$2:$K$501,SAISIE!$C$2:$C$501,LISTES!$E$6)+SUMIFS(SAISIE!$L$2:$L$501,SAISIE!$C$2:$C$501,LISTES!$E$6)+SUMIFS(SAISIE!$M$2:$M$501,SAISIE!$C$2:$C$501,LISTES!$E$6)+SUMIFS(SAISIE!$N$2:$N$501,SAISIE!$C$2:$C$501,LISTES!$E$6)) | H7: =IFERROR(IF(F7=0,"",F7-G7),"") | I7: =IFERROR(IF(F7=0,"",G7/F7),"")
A8: =LISTES!$E$7 | G8: =IF(LISTES!$E$7="",0,SUMIFS(SAISIE!$E$2:$E$501,SAISIE!$C$2:$C$501,LISTES!$E$7)+SUMIFS(SAISIE!$F$2:$F$501,SAISIE!$C$2:$C$501,LISTES!$E$7)+SUMIFS(SAISIE!$G$2:$G$501,SAISIE!$C$2:$C$501,LISTES!$E$7)+SUMIFS(SAISIE!$H$2:$H$501,SAISIE!$C$2:$C$501,LISTES!$E$7)+SUMIFS(SAISIE!$I$2:$I$501,SAISIE!$C$2:$C$501,LISTES!$E$7)+SUMIFS(SAISIE!$J$2:$J$501,SAISIE!$C$2:$C$501,LISTES!$E$7)+SUMIFS(SAISIE!$K$2:$K$501,SAISIE!$C$2:$C$501,LISTES!$E$7)+SUMIFS(SAISIE!$L$2:$L$501,SAISIE!$C$2:$C$501,LISTES!$E$7)+SUMIFS(SAISIE!$M$2:$M$501,SAISIE!$C$2:$C$501,LISTES!$E$7)+SUMIFS(SAISIE!$N$2:$N$501,SAISIE!$C$2:$C$501,LISTES!$E$7)) | H8: =IFERROR(IF(F8=0,"",F8-G8),"") | I8: =IFERROR(IF(F8=0,"",G8/F8),"")
A9: =LISTES!$E$8 | G9: =IF(LISTES!$E$8="",0,SUMIFS(SAISIE!$E$2:$E$501,SAISIE!$C$2:$C$501,LISTES!$E$8)+SUMIFS(SAISIE!$F$2:$F$501,SAISIE!$C$2:$C$501,LISTES!$E$8)+SUMIFS(SAISIE!$G$2:$G$501,SAISIE!$C$2:$C$501,LISTES!$E$8)+SUMIFS(SAISIE!$H$2:$H$501,SAISIE!$C$2:$C$501,LISTES!$E$8)+SUMIFS(SAISIE!$I$2:$I$501,SAISIE!$C$2:$C$501,LISTES!$E$8)+SUMIFS(SAISIE!$J$2:$J$501,SAISIE!$C$2:$C$501,LISTES!$E$8)+SUMIFS(SAISIE!$K$2:$K$501,SAISIE!$C$2:$C$501,LISTES!$E$8)+SUMIFS(SAISIE!$L$2:$L$501,SAISIE!$C$2:$C$501,LISTES!$E$8)+SUMIFS(SAISIE!$M$2:$M$501,SAISIE!$C$2:$C$501,LISTES!$E$8)+SUMIFS(SAISIE!$N$2:$N$501,SAISIE!$C$2:$C$501,LISTES!$E$8)) | H9: =IFERROR(IF(F9=0,"",F9-G9),"") | I9: =IFERROR(IF(F9=0,"",G9/F9),"")
A10: =LISTES!$E$9 | G10: =IF(LISTES!$E$9="",0,SUMIFS(SAISIE!$E$2:$E$501,SAISIE!$C$2:$C$501,LISTES!$E$9)+SUMIFS(SAISIE!$F$2:$F$501,SAISIE!$C$2:$C$501,LISTES!$E$9)+SUMIFS(SAISIE!$G$2:$G$501,SAISIE!$C$2:$C$501,LISTES!$E$9)+SUMIFS(SAISIE!$H$2:$H$501,SAISIE!$C$2:$C$501,LISTES!$E$9)+SUMIFS(SAISIE!$I$2:$I$501,SAISIE!$C$2:$C$501,LISTES!$E$9)+SUMIFS(SAISIE!$J$2:$J$501,SAISIE!$C$2:$C$501,LISTES!$E$9)+SUMIFS(SAISIE!$K$2:$K$501,SAISIE!$C$2:$C$501,LISTES!$E$9)+SUMIFS(SAISIE!$L$2:$L$501,SAISIE!$C$2:$C$501,LISTES!$E$9)+SUMIFS(SAISIE!$M$2:$M$501,SAISIE!$C$2:$C$501,LISTES!$E$9)+SUMIFS(SAISIE!$N$2:$N$501,SAISIE!$C$2:$C$501,LISTES!$E$9)) | H10: =IFERROR(IF(F10=0,"",F10-G10),"") | I10: =IFERROR(IF(F10=0,"",G10/F10),"")
A11: =LISTES!$E$10 | G11: =IF(LISTES!$E$10="",0,SUMIFS(SAISIE!$E$2:$E$501,SAISIE!$C$2:$C$501,LISTES!$E$10)+SUMIFS(SAISIE!$F$2:$F$501,SAISIE!$C$2:$C$501,LISTES!$E$10)+SUMIFS(SAISIE!$G$2:$G$501,SAISIE!$C$2:$C$501,LISTES!$E$10)+SUMIFS(SAISIE!$H$2:$H$501,SAISIE!$C$2:$C$501,LISTES!$E$10)+SUMIFS(SAISIE!$I$2:$I$501,SAISIE!$C$2:$C$501,LISTES!$E$10)+SUMIFS(SAISIE!$J$2:$J$501,SAISIE!$C$2:$C$501,LISTES!$E$10)+SUMIFS(SAISIE!$K$2:$K$501,SAISIE!$C$2:$C$501,LISTES!$E$10)+SUMIFS(SAISIE!$L$2:$L$501,SAISIE!$C$2:$C$501,LISTES!$E$10)+SUMIFS(SAISIE!$M$2:$M$501,SAISIE!$C$2:$C$501,LISTES!$E$10)+SUMIFS(SAISIE!$N$2:$N$501,SAISIE!$C$2:$C$501,LISTES!$E$10)) | H11: =IFERROR(IF(F11=0,"",F11-G11),"") | I11: =IFERROR(IF(F11=0,"",G11/F11),"")
A12: =LISTES!$E$11 | G12: =IF(LISTES!$E$11="",0,SUMIFS(SAISIE!$E$2:$E$501,SAISIE!$C$2:$C$501,LISTES!$E$11)+SUMIFS(SAISIE!$F$2:$F$501,SAISIE!$C$2:$C$501,LISTES!$E$11)+SUMIFS(SAISIE!$G$2:$G$501,SAISIE!$C$2:$C$501,LISTES!$E$11)+SUMIFS(SAISIE!$H$2:$H$501,SAISIE!$C$2:$C$501,LISTES!$E$11)+SUMIFS(SAISIE!$I$2:$I$501,SAISIE!$C$2:$C$501,LISTES!$E$11)+SUMIFS(SAISIE!$J$2:$J$501,SAISIE!$C$2:$C$501,LISTES!$E$11)+SUMIFS(SAISIE!$K$2:$K$501,SAISIE!$C$2:$C$501,LISTES!$E$11)+SUMIFS(SAISIE!$L$2:$L$501,SAISIE!$C$2:$C$501,LISTES!$E$11)+SUMIFS(SAISIE!$M$2:$M$501,SAISIE!$C$2:$C$501,LISTES!$E$11)+SUMIFS(SAISIE!$N$2:$N$501,SAISIE!$C$2:$C$501,LISTES!$E$11)) | H12: =IFERROR(IF(F12=0,"",F12-G12),"") | I12: =IFERROR(IF(F12=0,"",G12/F12),"")
A13: Sous-total | F13: =SUMIF(F3:F12,"<>") | G13: =SUM(G3:G12) | H13: =IFERROR(IF(F13=0,"",F13-G13),"") | I13: =IFERROR(IF(F13=0,"",G13/F13),"")
A15: ▸ RTR ZONE ORANGE
A16: RTR | B16: N° IZ | C16: Type | D16: Tranche | E16: Local | F16: Prévu (mSv) | G16: Consommé (mSv) | H16: Reste (mSv) | I16: % consommé
A17: =LISTES!$G$2 | G17: =IF(LISTES!$G$2="",0,SUMIFS(SAISIE!$E$2:$E$501,SAISIE!$C$2:$C$501,LISTES!$G$2)+SUMIFS(SAISIE!$F$2:$F$501,SAISIE!$C$2:$C$501,LISTES!$G$2)+SUMIFS(SAISIE!$G$2:$G$501,SAISIE!$C$2:$C$501,LISTES!$G$2)+SUMIFS(SAISIE!$H$2:$H$501,SAISIE!$C$2:$C$501,LISTES!$G$2)+SUMIFS(SAISIE!$I$2:$I$501,SAISIE!$C$2:$C$501,LISTES!$G$2)+SUMIFS(SAISIE!$J$2:$J$501,SAISIE!$C$2:$C$501,LISTES!$G$2)+SUMIFS(SAISIE!$K$2:$K$501,SAISIE!$C$2:$C$501,LISTES!$G$2)+SUMIFS(SAISIE!$L$2:$L$501,SAISIE!$C$2:$C$501,LISTES!$G$2)+SUMIFS(SAISIE!$M$2:$M$501,SAISIE!$C$2:$C$501,LISTES!$G$2)+SUMIFS(SAISIE!$N$2:$N$501,SAISIE!$C$2:$C$501,LISTES!$G$2)) | H17: =IFERROR(IF(F17=0,"",F17-G17),"") | I17: =IFERROR(IF(F17=0,"",G17/F17),"")
A18: =LISTES!$G$3 | G18: =IF(LISTES!$G$3="",0,SUMIFS(SAISIE!$E$2:$E$501,SAISIE!$C$2:$C$501,LISTES!$G$3)+SUMIFS(SAISIE!$F$2:$F$501,SAISIE!$C$2:$C$501,LISTES!$G$3)+SUMIFS(SAISIE!$G$2:$G$501,SAISIE!$C$2:$C$501,LISTES!$G$3)+SUMIFS(SAISIE!$H$2:$H$501,SAISIE!$C$2:$C$501,LISTES!$G$3)+SUMIFS(SAISIE!$I$2:$I$501,SAISIE!$C$2:$C$501,LISTES!$G$3)+SUMIFS(SAISIE!$J$2:$J$501,SAISIE!$C$2:$C$501,LISTES!$G$3)+SUMIFS(SAISIE!$K$2:$K$501,SAISIE!$C$2:$C$501,LISTES!$G$3)+SUMIFS(SAISIE!$L$2:$L$501,SAISIE!$C$2:$C$501,LISTES!$G$3)+SUMIFS(SAISIE!$M$2:$M$501,SAISIE!$C$2:$C$501,LISTES!$G$3)+SUMIFS(SAISIE!$N$2:$N$501,SAISIE!$C$2:$C$501,LISTES!$G$3)) | H18: =IFERROR(IF(F18=0,"",F18-G18),"") | I18: =IFERROR(IF(F18=0,"",G18/F18),"")
A19: =LISTES!$G$4 | G19: =IF(LISTES!$G$4="",0,SUMIFS(SAISIE!$E$2:$E$501,SAISIE!$C$2:$C$501,LISTES!$G$4)+SUMIFS(SAISIE!$F$2:$F$501,SAISIE!$C$2:$C$501,LISTES!$G$4)+SUMIFS(SAISIE!$G$2:$G$501,SAISIE!$C$2:$C$501,LISTES!$G$4)+SUMIFS(SAISIE!$H$2:$H$501,SAISIE!$C$2:$C$501,LISTES!$G$4)+SUMIFS(SAISIE!$I$2:$I$501,SAISIE!$C$2:$C$501,LISTES!$G$4)+SUMIFS(SAISIE!$J$2:$J$501,SAISIE!$C$2:$C$501,LISTES!$G$4)+SUMIFS(SAISIE!$K$2:$K$501,SAISIE!$C$2:$C$501,LISTES!$G$4)+SUMIFS(SAISIE!$L$2:$L$501,SAISIE!$C$2:$C$501,LISTES!$G$4)+SUMIFS(SAISIE!$M$2:$M$501,SAISIE!$C$2:$C$501,LISTES!$G$4)+SUMIFS(SAISIE!$N$2:$N$501,SAISIE!$C$2:$C$501,LISTES!$G$4)) | H19: =IFERROR(IF(F19=0,"",F19-G19),"") | I19: =IFERROR(IF(F19=0,"",G19/F19),"")
A20: =LISTES!$G$5 | G20: =IF(LISTES!$G$5="",0,SUMIFS(SAISIE!$E$2:$E$501,SAISIE!$C$2:$C$501,LISTES!$G$5)+SUMIFS(SAISIE!$F$2:$F$501,SAISIE!$C$2:$C$501,LISTES!$G$5)+SUMIFS(SAISIE!$G$2:$G$501,SAISIE!$C$2:$C$501,LISTES!$G$5)+SUMIFS(SAISIE!$H$2:$H$501,SAISIE!$C$2:$C$501,LISTES!$G$5)+SUMIFS(SAISIE!$I$2:$I$501,SAISIE!$C$2:$C$501,LISTES!$G$5)+SUMIFS(SAISIE!$J$2:$J$501,SAISIE!$C$2:$C$501,LISTES!$G$5)+SUMIFS(SAISIE!$K$2:$K$501,SAISIE!$C$2:$C$501,LISTES!$G$5)+SUMIFS(SAISIE!$L$2:$L$501,SAISIE!$C$2:$C$501,LISTES!$G$5)+SUMIFS(SAISIE!$M$2:$M$501,SAISIE!$C$2:$C$501,LISTES!$G$5)+SUMIFS(SAISIE!$N$2:$N$501,SAISIE!$C$2:$C$501,LISTES!$G$5)) | H20: =IFERROR(IF(F20=0,"",F20-G20),"") | I20: =IFERROR(IF(F20=0,"",G20/F20),"")
A21: =LISTES!$G$6 | G21: =IF(LISTES!$G$6="",0,SUMIFS(SAISIE!$E$2:$E$501,SAISIE!$C$2:$C$501,LISTES!$G$6)+SUMIFS(SAISIE!$F$2:$F$501,SAISIE!$C$2:$C$501,LISTES!$G$6)+SUMIFS(SAISIE!$G$2:$G$501,SAISIE!$C$2:$C$501,LISTES!$G$6)+SUMIFS(SAISIE!$H$2:$H$501,SAISIE!$C$2:$C$501,LISTES!$G$6)+SUMIFS(SAISIE!$I$2:$I$501,SAISIE!$C$2:$C$501,LISTES!$G$6)+SUMIFS(SAISIE!$J$2:$J$501,SAISIE!$C$2:$C$501,LISTES!$G$6)+SUMIFS(SAISIE!$K$2:$K$501,SAISIE!$C$2:$C$501,LISTES!$G$6)+SUMIFS(SAISIE!$L$2:$L$501,SAISIE!$C$2:$C$501,LISTES!$G$6)+SUMIFS(SAISIE!$M$2:$M$501,SAISIE!$C$2:$C$501,LISTES!$G$6)+SUMIFS(SAISIE!$N$2:$N$501,SAISIE!$C$2:$C$501,LISTES!$G$6)) | H21: =IFERROR(IF(F21=0,"",F21-G21),"") | I21: =IFERROR(IF(F21=0,"",G21/F21),"")
A22: =LISTES!$G$7 | G22: =IF(LISTES!$G$7="",0,SUMIFS(SAISIE!$E$2:$E$501,SAISIE!$C$2:$C$501,LISTES!$G$7)+SUMIFS(SAISIE!$F$2:$F$501,SAISIE!$C$2:$C$501,LISTES!$G$7)+SUMIFS(SAISIE!$G$2:$G$501,SAISIE!$C$2:$C$501,LISTES!$G$7)+SUMIFS(SAISIE!$H$2:$H$501,SAISIE!$C$2:$C$501,LISTES!$G$7)+SUMIFS(SAISIE!$I$2:$I$501,SAISIE!$C$2:$C$501,LISTES!$G$7)+SUMIFS(SAISIE!$J$2:$J$501,SAISIE!$C$2:$C$501,LISTES!$G$7)+SUMIFS(SAISIE!$K$2:$K$501,SAISIE!$C$2:$C$501,LISTES!$G$7)+SUMIFS(SAISIE!$L$2:$L$501,SAISIE!$C$2:$C$501,LISTES!$G$7)+SUMIFS(SAISIE!$M$2:$M$501,SAISIE!$C$2:$C$501,LISTES!$G$7)+SUMIFS(SAISIE!$N$2:$N$501,SAISIE!$C$2:$C$501,LISTES!$G$7)) | H22: =IFERROR(IF(F22=0,"",F22-G22),"") | I22: =IFERROR(IF(F22=0,"",G22/F22),"")
A23: =LISTES!$G$8 | G23: =IF(LISTES!$G$8="",0,SUMIFS(SAISIE!$E$2:$E$501,SAISIE!$C$2:$C$501,LISTES!$G$8)+SUMIFS(SAISIE!$F$2:$F$501,SAISIE!$C$2:$C$501,LISTES!$G$8)+SUMIFS(SAISIE!$G$2:$G$501,SAISIE!$C$2:$C$501,LISTES!$G$8)+SUMIFS(SAISIE!$H$2:$H$501,SAISIE!$C$2:$C$501,LISTES!$G$8)+SUMIFS(SAISIE!$I$2:$I$501,SAISIE!$C$2:$C$501,LISTES!$G$8)+SUMIFS(SAISIE!$J$2:$J$501,SAISIE!$C$2:$C$501,LISTES!$G$8)+SUMIFS(SAISIE!$K$2:$K$501,SAISIE!$C$2:$C$501,LISTES!$G$8)+SUMIFS(SAISIE!$L$2:$L$501,SAISIE!$C$2:$C$501,LISTES!$G$8)+SUMIFS(SAISIE!$M$2:$M$501,SAISIE!$C$2:$C$501,LISTES!$G$8)+SUMIFS(SAISIE!$N$2:$N$501,SAISIE!$C$2:$C$501,LISTES!$G$8)) | H23: =IFERROR(IF(F23=0,"",F23-G23),"") | I23: =IFERROR(IF(F23=0,"",G23/F23),"")
A24: =LISTES!$G$9 | G24: =IF(LISTES!$G$9="",0,SUMIFS(SAISIE!$E$2:$E$501,SAISIE!$C$2:$C$501,LISTES!$G$9)+SUMIFS(SAISIE!$F$2:$F$501,SAISIE!$C$2:$C$501,LISTES!$G$9)+SUMIFS(SAISIE!$G$2:$G$501,SAISIE!$C$2:$C$501,LISTES!$G$9)+SUMIFS(SAISIE!$H$2:$H$501,SAISIE!$C$2:$C$501,LISTES!$G$9)+SUMIFS(SAISIE!$I$2:$I$501,SAISIE!$C$2:$C$501,LISTES!$G$9)+SUMIFS(SAISIE!$J$2:$J$501,SAISIE!$C$2:$C$501,LISTES!$G$9)+SUMIFS(SAISIE!$K$2:$K$501,SAISIE!$C$2:$C$501,LISTES!$G$9)+SUMIFS(SAISIE!$L$2:$L$501,SAISIE!$C$2:$C$501,LISTES!$G$9)+SUMIFS(SAISIE!$M$2:$M$501,SAISIE!$C$2:$C$501,LISTES!$G$9)+SUMIFS(SAISIE!$N$2:$N$501,SAISIE!$C$2:$C$501,LISTES!$G$9)) | H24: =IFERROR(IF(F24=0,"",F24-G24),"") | I24: =IFERROR(IF(F24=0,"",G24/F24),"")
A25: =LISTES!$G$10 | G25: =IF(LISTES!$G$10="",0,SUMIFS(SAISIE!$E$2:$E$501,SAISIE!$C$2:$C$501,LISTES!$G$10)+SUMIFS(SAISIE!$F$2:$F$501,SAISIE!$C$2:$C$501,LISTES!$G$10)+SUMIFS(SAISIE!$G$2:$G$501,SAISIE!$C$2:$C$501,LISTES!$G$10)+SUMIFS(SAISIE!$H$2:$H$501,SAISIE!$C$2:$C$501,LISTES!$G$10)+SUMIFS(SAISIE!$I$2:$I$501,SAISIE!$C$2:$C$501,LISTES!$G$10)+SUMIFS(SAISIE!$J$2:$J$501,SAISIE!$C$2:$C$501,LISTES!$G$10)+SUMIFS(SAISIE!$K$2:$K$501,SAISIE!$C$2:$C$501,LISTES!$G$10)+SUMIFS(SAISIE!$L$2:$L$501,SAISIE!$C$2:$C$501,LISTES!$G$10)+SUMIFS(SAISIE!$M$2:$M$501,SAISIE!$C$2:$C$501,LISTES!$G$10)+SUMIFS(SAISIE!$N$2:$N$501,SAISIE!$C$2:$C$501,LISTES!$G$10)) | H25: =IFERROR(IF(F25=0,"",F25-G25),"") | I25: =IFERROR(IF(F25=0,"",G25/F25),"")
A26: =LISTES!$G$11 | G26: =IF(LISTES!$G$11="",0,SUMIFS(SAISIE!$E$2:$E$501,SAISIE!$C$2:$C$501,LISTES!$G$11)+SUMIFS(SAISIE!$F$2:$F$501,SAISIE!$C$2:$C$501,LISTES!$G$11)+SUMIFS(SAISIE!$G$2:$G$501,SAISIE!$C$2:$C$501,LISTES!$G$11)+SUMIFS(SAISIE!$H$2:$H$501,SAISIE!$C$2:$C$501,LISTES!$G$11)+SUMIFS(SAISIE!$I$2:$I$501,SAISIE!$C$2:$C$501,LISTES!$G$11)+SUMIFS(SAISIE!$J$2:$J$501,SAISIE!$C$2:$C$501,LISTES!$G$11)+SUMIFS(SAISIE!$K$2:$K$501,SAISIE!$C$2:$C$501,LISTES!$G$11)+SUMIFS(SAISIE!$L$2:$L$501,SAISIE!$C$2:$C$501,LISTES!$G$11)+SUMIFS(SAISIE!$M$2:$M$501,SAISIE!$C$2:$C$501,LISTES!$G$11)+SUMIFS(SAISIE!$N$2:$N$501,SAISIE!$C$2:$C$501,LISTES!$G$11)) | H26: =IFERROR(IF(F26=0,"",F26-G26),"") | I26: =IFERROR(IF(F26=0,"",G26/F26),"")
A27: Sous-total | F27: =SUMIF(F17:F26,"<>") | G27: =SUM(G17:G26) | H27: =IFERROR(IF(F27=0,"",F27-G27),"") | I27: =IFERROR(IF(F27=0,"",G27/F27),"")
A29: ▸ RTR NEUTRONIQUES
A30: RTR | B30: N° IZ | C30: Type | D30: Tranche | E30: Local | F30: Prévu (mSv) | G30: Consommé (mSv) | H30: Reste (mSv) | I30: % consommé
A31: =LISTES!$I$2 | G31: =IF(LISTES!$I$2="",0,SUMIFS(SAISIE!$E$2:$E$501,SAISIE!$C$2:$C$501,LISTES!$I$2)+SUMIFS(SAISIE!$F$2:$F$501,SAISIE!$C$2:$C$501,LISTES!$I$2)+SUMIFS(SAISIE!$G$2:$G$501,SAISIE!$C$2:$C$501,LISTES!$I$2)+SUMIFS(SAISIE!$H$2:$H$501,SAISIE!$C$2:$C$501,LISTES!$I$2)+SUMIFS(SAISIE!$I$2:$I$501,SAISIE!$C$2:$C$501,LISTES!$I$2)+SUMIFS(SAISIE!$J$2:$J$501,SAISIE!$C$2:$C$501,LISTES!$I$2)+SUMIFS(SAISIE!$K$2:$K$501,SAISIE!$C$2:$C$501,LISTES!$I$2)+SUMIFS(SAISIE!$L$2:$L$501,SAISIE!$C$2:$C$501,LISTES!$I$2)+SUMIFS(SAISIE!$M$2:$M$501,SAISIE!$C$2:$C$501,LISTES!$I$2)+SUMIFS(SAISIE!$N$2:$N$501,SAISIE!$C$2:$C$501,LISTES!$I$2)) | H31: =IFERROR(IF(F31=0,"",F31-G31),"") | I31: =IFERROR(IF(F31=0,"",G31/F31),"")
A32: =LISTES!$I$3 | G32: =IF(LISTES!$I$3="",0,SUMIFS(SAISIE!$E$2:$E$501,SAISIE!$C$2:$C$501,LISTES!$I$3)+SUMIFS(SAISIE!$F$2:$F$501,SAISIE!$C$2:$C$501,LISTES!$I$3)+SUMIFS(SAISIE!$G$2:$G$501,SAISIE!$C$2:$C$501,LISTES!$I$3)+SUMIFS(SAISIE!$H$2:$H$501,SAISIE!$C$2:$C$501,LISTES!$I$3)+SUMIFS(SAISIE!$I$2:$I$501,SAISIE!$C$2:$C$501,LISTES!$I$3)+SUMIFS(SAISIE!$J$2:$J$501,SAISIE!$C$2:$C$501,LISTES!$I$3)+SUMIFS(SAISIE!$K$2:$K$501,SAISIE!$C$2:$C$501,LISTES!$I$3)+SUMIFS(SAISIE!$L$2:$L$501,SAISIE!$C$2:$C$501,LISTES!$I$3)+SUMIFS(SAISIE!$M$2:$M$501,SAISIE!$C$2:$C$501,LISTES!$I$3)+SUMIFS(SAISIE!$N$2:$N$501,SAISIE!$C$2:$C$501,LISTES!$I$3)) | H32: =IFERROR(IF(F32=0,"",F32-G32),"") | I32: =IFERROR(IF(F32=0,"",G32/F32),"")
A33: =LISTES!$I$4 | G33: =IF(LISTES!$I$4="",0,SUMIFS(SAISIE!$E$2:$E$501,SAISIE!$C$2:$C$501,LISTES!$I$4)+SUMIFS(SAISIE!$F$2:$F$501,SAISIE!$C$2:$C$501,LISTES!$I$4)+SUMIFS(SAISIE!$G$2:$G$501,SAISIE!$C$2:$C$501,LISTES!$I$4)+SUMIFS(SAISIE!$H$2:$H$501,SAISIE!$C$2:$C$501,LISTES!$I$4)+SUMIFS(SAISIE!$I$2:$I$501,SAISIE!$C$2:$C$501,LISTES!$I$4)+SUMIFS(SAISIE!$J$2:$J$501,SAISIE!$C$2:$C$501,LISTES!$I$4)+SUMIFS(SAISIE!$K$2:$K$501,SAISIE!$C$2:$C$501,LISTES!$I$4)+SUMIFS(SAISIE!$L$2:$L$501,SAISIE!$C$2:$C$501,LISTES!$I$4)+SUMIFS(SAISIE!$M$2:$M$501,SAISIE!$C$2:$C$501,LISTES!$I$4)+SUMIFS(SAISIE!$N$2:$N$501,SAISIE!$C$2:$C$501,LISTES!$I$4)) | H33: =IFERROR(IF(F33=0,"",F33-G33),"") | I33: =IFERROR(IF(F33=0,"",G33/F33),"")
A34: =LISTES!$I$5 | G34: =IF(LISTES!$I$5="",0,SUMIFS(SAISIE!$E$2:$E$501,SAISIE!$C$2:$C$501,LISTES!$I$5)+SUMIFS(SAISIE!$F$2:$F$501,SAISIE!$C$2:$C$501,LISTES!$I$5)+SUMIFS(SAISIE!$G$2:$G$501,SAISIE!$C$2:$C$501,LISTES!$I$5)+SUMIFS(SAISIE!$H$2:$H$501,SAISIE!$C$2:$C$501,LISTES!$I$5)+SUMIFS(SAISIE!$I$2:$I$501,SAISIE!$C$2:$C$501,LISTES!$I$5)+SUMIFS(SAISIE!$J$2:$J$501,SAISIE!$C$2:$C$501,LISTES!$I$5)+SUMIFS(SAISIE!$K$2:$K$501,SAISIE!$C$2:$C$501,LISTES!$I$5)+SUMIFS(SAISIE!$L$2:$L$501,SAISIE!$C$2:$C$501,LISTES!$I$5)+SUMIFS(SAISIE!$M$2:$M$501,SAISIE!$C$2:$C$501,LISTES!$I$5)+SUMIFS(SAISIE!$N$2:$N$501,SAISIE!$C$2:$C$501,LISTES!$I$5)) | H34: =IFERROR(IF(F34=0,"",F34-G34),"") | I34: =IFERROR(IF(F34=0,"",G34/F34),"")
A35: =LISTES!$I$6 | G35: =IF(LISTES!$I$6="",0,SUMIFS(SAISIE!$E$2:$E$501,SAISIE!$C$2:$C$501,LISTES!$I$6)+SUMIFS(SAISIE!$F$2:$F$501,SAISIE!$C$2:$C$501,LISTES!$I$6)+SUMIFS(SAISIE!$G$2:$G$501,SAISIE!$C$2:$C$501,LISTES!$I$6)+SUMIFS(SAISIE!$H$2:$H$501,SAISIE!$C$2:$C$501,LISTES!$I$6)+SUMIFS(SAISIE!$I$2:$I$501,SAISIE!$C$2:$C$501,LISTES!$I$6)+SUMIFS(SAISIE!$J$2:$J$501,SAISIE!$C$2:$C$501,LISTES!$I$6)+SUMIFS(SAISIE!$K$2:$K$501,SAISIE!$C$2:$C$501,LISTES!$I$6)+SUMIFS(SAISIE!$L$2:$L$501,SAISIE!$C$2:$C$501,LISTES!$I$6)+SUMIFS(SAISIE!$M$2:$M$501,SAISIE!$C$2:$C$501,LISTES!$I$6)+SUMIFS(SAISIE!$N$2:$N$501,SAISIE!$C$2:$C$501,LISTES!$I$6)) | H35: =IFERROR(IF(F35=0,"",F35-G35),"") | I35: =IFERROR(IF(F35=0,"",G35/F35),"")
A36: =LISTES!$I$7 | G36: =IF(LISTES!$I$7="",0,SUMIFS(SAISIE!$E$2:$E$501,SAISIE!$C$2:$C$501,LISTES!$I$7)+SUMIFS(SAISIE!$F$2:$F$501,SAISIE!$C$2:$C$501,LISTES!$I$7)+SUMIFS(SAISIE!$G$2:$G$501,SAISIE!$C$2:$C$501,LISTES!$I$7)+SUMIFS(SAISIE!$H$2:$H$501,SAISIE!$C$2:$C$501,LISTES!$I$7)+SUMIFS(SAISIE!$I$2:$I$501,SAISIE!$C$2:$C$501,LISTES!$I$7)+SUMIFS(SAISIE!$J$2:$J$501,SAISIE!$C$2:$C$501,LISTES!$I$7)+SUMIFS(SAISIE!$K$2:$K$501,SAISIE!$C$2:$C$501,LISTES!$I$7)+SUMIFS(SAISIE!$L$2:$L$501,SAISIE!$C$2:$C$501,LISTES!$I$7)+SUMIFS(SAISIE!$M$2:$M$501,SAISIE!$C$2:$C$501,LISTES!$I$7)+SUMIFS(SAISIE!$N$2:$N$501,SAISIE!$C$2:$C$501,LISTES!$I$7)) | H36: =IFERROR(IF(F36=0,"",F36-G36),"") | I36: =IFERROR(IF(F36=0,"",G36/F36),"")
A37: =LISTES!$I$8 | G37: =IF(LISTES!$I$8="",0,SUMIFS(SAISIE!$E$2:$E$501,SAISIE!$C$2:$C$501,LISTES!$I$8)+SUMIFS(SAISIE!$F$2:$F$501,SAISIE!$C$2:$C$501,LISTES!$I$8)+SUMIFS(SAISIE!$G$2:$G$501,SAISIE!$C$2:$C$501,LISTES!$I$8)+SUMIFS(SAISIE!$H$2:$H$501,SAISIE!$C$2:$C$501,LISTES!$I$8)+SUMIFS(SAISIE!$I$2:$I$501,SAISIE!$C$2:$C$501,LISTES!$I$8)+SUMIFS(SAISIE!$J$2:$J$501,SAISIE!$C$2:$C$501,LISTES!$I$8)+SUMIFS(SAISIE!$K$2:$K$501,SAISIE!$C$2:$C$501,LISTES!$I$8)+SUMIFS(SAISIE!$L$2:$L$501,SAISIE!$C$2:$C$501,LISTES!$I$8)+SUMIFS(SAISIE!$M$2:$M$501,SAISIE!$C$2:$C$501,LISTES!$I$8)+SUMIFS(SAISIE!$N$2:$N$501,SAISIE!$C$2:$C$501,LISTES!$I$8)) | H37: =IFERROR(IF(F37=0,"",F37-G37),"") | I37: =IFERROR(IF(F37=0,"",G37/F37),"")
A38: =LISTES!$I$9 | G38: =IF(LISTES!$I$9="",0,SUMIFS(SAISIE!$E$2:$E$501,SAISIE!$C$2:$C$501,LISTES!$I$9)+SUMIFS(SAISIE!$F$2:$F$501,SAISIE!$C$2:$C$501,LISTES!$I$9)+SUMIFS(SAISIE!$G$2:$G$501,SAISIE!$C$2:$C$501,LISTES!$I$9)+SUMIFS(SAISIE!$H$2:$H$501,SAISIE!$C$2:$C$501,LISTES!$I$9)+SUMIFS(SAISIE!$I$2:$I$501,SAISIE!$C$2:$C$501,LISTES!$I$9)+SUMIFS(SAISIE!$J$2:$J$501,SAISIE!$C$2:$C$501,LISTES!$I$9)+SUMIFS(SAISIE!$K$2:$K$501,SAISIE!$C$2:$C$501,LISTES!$I$9)+SUMIFS(SAISIE!$L$2:$L$501,SAISIE!$C$2:$C$501,LISTES!$I$9)+SUMIFS(SAISIE!$M$2:$M$501,SAISIE!$C$2:$C$501,LISTES!$I$9)+SUMIFS(SAISIE!$N$2:$N$501,SAISIE!$C$2:$C$501,LISTES!$I$9)) | H38: =IFERROR(IF(F38=0,"",F38-G38),"") | I38: =IFERROR(IF(F38=0,"",G38/F38),"")
A39: =LISTES!$I$10 | G39: =IF(LISTES!$I$10="",0,SUMIFS(SAISIE!$E$2:$E$501,SAISIE!$C$2:$C$501,LISTES!$I$10)+SUMIFS(SAISIE!$F$2:$F$501,SAISIE!$C$2:$C$501,LISTES!$I$10)+SUMIFS(SAISIE!$G$2:$G$501,SAISIE!$C$2:$C$501,LISTES!$I$10)+SUMIFS(SAISIE!$H$2:$H$501,SAISIE!$C$2:$C$501,LISTES!$I$10)+SUMIFS(SAISIE!$I$2:$I$501,SAISIE!$C$2:$C$501,LISTES!$I$10)+SUMIFS(SAISIE!$J$2:$J$501,SAISIE!$C$2:$C$501,LISTES!$I$10)+SUMIFS(SAISIE!$K$2:$K$501,SAISIE!$C$2:$C$501,LISTES!$I$10)+SUMIFS(SAISIE!$L$2:$L$501,SAISIE!$C$2:$C$501,LISTES!$I$10)+SUMIFS(SAISIE!$M$2:$M$501,SAISIE!$C$2:$C$501,LISTES!$I$10)+SUMIFS(SAISIE!$N$2:$N$501,SAISIE!$C$2:$C$501,LISTES!$I$10)) | H39: =IFERROR(IF(F39=0,"",F39-G39),"") | I39: =IFERROR(IF(F39=0,"",G39/F39),"")
A40: =LISTES!$I$11 | G40: =IF(LISTES!$I$11="",0,SUMIFS(SAISIE!$E$2:$E$501,SAISIE!$C$2:$C$501,LISTES!$I$11)+SUMIFS(SAISIE!$F$2:$F$501,SAISIE!$C$2:$C$501,LISTES!$I$11)+SUMIFS(SAISIE!$G$2:$G$501,SAISIE!$C$2:$C$501,LISTES!$I$11)+SUMIFS(SAISIE!$H$2:$H$501,SAISIE!$C$2:$C$501,LISTES!$I$11)+SUMIFS(SAISIE!$I$2:$I$501,SAISIE!$C$2:$C$501,LISTES!$I$11)+SUMIFS(SAISIE!$J$2:$J$501,SAISIE!$C$2:$C$501,LISTES!$I$11)+SUMIFS(SAISIE!$K$2:$K$501,SAISIE!$C$2:$C$501,LISTES!$I$11)+SUMIFS(SAISIE!$L$2:$L$501,SAISIE!$C$2:$C$501,LISTES!$I$11)+SUMIFS(SAISIE!$M$2:$M$501,SAISIE!$C$2:$C$501,LISTES!$I$11)+SUMIFS(SAISIE!$N$2:$N$501,SAISIE!$C$2:$C$501,LISTES!$I$11)) | H40: =IFERROR(IF(F40=0,"",F40-G40),"") | I40: =IFERROR(IF(F40=0,"",G40/F40),"")
A41: Sous-total | F41: =SUMIF(F31:F40,"<>") | G41: =SUM(G31:G40) | H41: =IFERROR(IF(F41=0,"",F41-G41),"") | I41: =IFERROR(IF(F41=0,"",G41/F41),"")
A42: TOTAL GÉNÉRAL | F42: =SUM(F13,F27,F41) | G42: =SUM(G13,G27,G41) | H42: =IFERROR(IF(F42=0,"",F42-G42),"") | I42: =IFERROR(IF(F42=0,"",G42/F42),"")

Sheet SUIVI_BATIMENT
A1: SUIVI PAR BÂTIMENT
A2: Bâtiment | B2: Dose consommée (mSv) | C2: Passages (DJ) | D2: Jours-Homme | E2: Jours Calendrier
A3: =LISTES!$K$2 | B3: =IF(LISTES!$K$2="",0,SUMIFS(SAISIE!$E$2:$E$501,SAISIE!$D$2:$D$501,LISTES!$K$2)+SUMIFS(SAISIE!$F$2:$F$501,SAISIE!$D$2:$D$501,LISTES!$K$2)+SUMIFS(SAISIE!$G$2:$G$501,SAISIE!$D$2:$D$501,LISTES!$K$2)+SUMIFS(SAISIE!$H$2:$H$501,SAISIE!$D$2:$D$501,LISTES!$K$2)+SUMIFS(SAISIE!$I$2:$I$501,SAISIE!$D$2:$D$501,LISTES!$K$2)+SUMIFS(SAISIE!$J$2:$J$501,SAISIE!$D$2:$D$501,LISTES!$K$2)+SUMIFS(SAISIE!$K$2:$K$501,SAISIE!$D$2:$D$501,LISTES!$K$2)+SUMIFS(SAISIE!$L$2:$L$501,SAISIE!$D$2:$D$501,LISTES!$K$2)+SUMIFS(SAISIE!$M$2:$M$501,SAISIE!$D$2:$D$501,LISTES!$K$2)+SUMIFS(SAISIE!$N$2:$N$501,SAISIE!$D$2:$D$501,LISTES!$K$2)) | C3: =IFERROR(COUNTIFS(SAISIE!$D$2:$D$501,LISTES!$K$2),0) | D3: =IFERROR(SUMPRODUCT((SAISIE!$D$2:$D$501=LISTES!$K$2)*((SAISIE!$E$2:$E$501>0)+(SAISIE!$F$2:$F$501>0)+(SAISIE!$G$2:$G$501>0)+(SAISIE!$H$2:$H$501>0)+(SAISIE!$I$2:$I$501>0)+(SAISIE!$J$2:$J$501>0)+(SAISIE!$K$2:$K$501>0)+(SAISIE!$L$2:$L$501>0)+(SAISIE!$M$2:$M$501>0)+(SAISIE!$N$2:$N$501>0))),0) | E3: =IFERROR(SUMPRODUCT((SAISIE!$D$2:$D$501=LISTES!$K$2)/(COUNTIFS(SAISIE!$A$2:$A$501,SAISIE!$A$2:$A$501,SAISIE!$D$2:$D$501,LISTES!$K$2)+((SAISIE!$D$2:$D$501<>LISTES!$K$2)*1E9))),0)
A4: =LISTES!$K$3 | B4: =IF(LISTES!$K$3="",0,SUMIFS(SAISIE!$E$2:$E$501,SAISIE!$D$2:$D$501,LISTES!$K$3)+SUMIFS(SAISIE!$F$2:$F$501,SAISIE!$D$2:$D$501,LISTES!$K$3)+SUMIFS(SAISIE!$G$2:$G$501,SAISIE!$D$2:$D$501,LISTES!$K$3)+SUMIFS(SAISIE!$H$2:$H$501,SAISIE!$D$2:$D$501,LISTES!$K$3)+SUMIFS(SAISIE!$I$2:$I$501,SAISIE!$D$2:$D$501,LISTES!$K$3)+SUMIFS(SAISIE!$J$2:$J$501,SAISIE!$D$2:$D$501,LISTES!$K$3)+SUMIFS(SAISIE!$K$2:$K$501,SAISIE!$D$2:$D$501,LISTES!$K$3)+SUMIFS(SAISIE!$L$2:$L$501,SAISIE!$D$2:$D$501,LISTES!$K$3)+SUMIFS(SAISIE!$M$2:$M$501,SAISIE!$D$2:$D$501,LISTES!$K$3)+SUMIFS(SAISIE!$N$2:$N$501,SAISIE!$D$2:$D$501,LISTES!$K$3)) | C4: =IFERROR(COUNTIFS(SAISIE!$D$2:$D$501,LISTES!$K$3),0) | D4: =IFERROR(SUMPRODUCT((SAISIE!$D$2:$D$501=LISTES!$K$3)*((SAISIE!$E$2:$E$501>0)+(SAISIE!$F$2:$F$501>0)+(SAISIE!$G$2:$G$501>0)+(SAISIE!$H$2:$H$501>0)+(SAISIE!$I$2:$I$501>0)+(SAISIE!$J$2:$J$501>0)+(SAISIE!$K$2:$K$501>0)+(SAISIE!$L$2:$L$501>0)+(SAISIE!$M$2:$M$501>0)+(SAISIE!$N$2:$N$501>0))),0) | E4: =IFERROR(SUMPRODUCT((SAISIE!$D$2:$D$501=LISTES!$K$3)/(COUNTIFS(SAISIE!$A$2:$A$501,SAISIE!$A$2:$A$501,SAISIE!$D$2:$D$501,LISTES!$K$3)+((SAISIE!$D$2:$D$501<>LISTES!$K$3)*1E9))),0)
A5: =LISTES!$K$4 | B5: =IF(LISTES!$K$4="",0,SUMIFS(SAISIE!$E$2:$E$501,SAISIE!$D$2:$D$501,LISTES!$K$4)+SUMIFS(SAISIE!$F$2:$F$501,SAISIE!$D$2:$D$501,LISTES!$K$4)+SUMIFS(SAISIE!$G$2:$G$501,SAISIE!$D$2:$D$501,LISTES!$K$4)+SUMIFS(SAISIE!$H$2:$H$501,SAISIE!$D$2:$D$501,LISTES!$K$4)+SUMIFS(SAISIE!$I$2:$I$501,SAISIE!$D$2:$D$501,LISTES!$K$4)+SUMIFS(SAISIE!$J$2:$J$501,SAISIE!$D$2:$D$501,LISTES!$K$4)+SUMIFS(SAISIE!$K$2:$K$501,SAISIE!$D$2:$D$501,LISTES!$K$4)+SUMIFS(SAISIE!$L$2:$L$501,SAISIE!$D$2:$D$501,LISTES!$K$4)+SUMIFS(SAISIE!$M$2:$M$501,SAISIE!$D$2:$D$501,LISTES!$K$4)+SUMIFS(SAISIE!$N$2:$N$501,SAISIE!$D$2:$D$501,LISTES!$K$4)) | C5: =IFERROR(COUNTIFS(SAISIE!$D$2:$D$501,LISTES!$K$4),0) | D5: =IFERROR(SUMPRODUCT((SAISIE!$D$2:$D$501=LISTES!$K$4)*((SAISIE!$E$2:$E$501>0)+(SAISIE!$F$2:$F$501>0)+(SAISIE!$G$2:$G$501>0)+(SAISIE!$H$2:$H$501>0)+(SAISIE!$I$2:$I$501>0)+(SAISIE!$J$2:$J$501>0)+(SAISIE!$K$2:$K$501>0)+(SAISIE!$L$2:$L$501>0)+(SAISIE!$M$2:$M$501>0)+(SAISIE!$N$2:$N$501>0))),0) | E5: =IFERROR(SUMPRODUCT((SAISIE!$D$2:$D$501=LISTES!$K$4)/(COUNTIFS(SAISIE!$A$2:$A$501,SAISIE!$A$2:$A$501,SAISIE!$D$2:$D$501,LISTES!$K$4)+((SAISIE!$D$2:$D$501<>LISTES!$K$4)*1E9))),0)
A6: =LISTES!$K$5 | B6: =IF(LISTES!$K$5="",0,SUMIFS(SAISIE!$E$2:$E$501,SAISIE!$D$2:$D$501,LISTES!$K$5)+SUMIFS(SAISIE!$F$2:$F$501,SAISIE!$D$2:$D$501,LISTES!$K$5)+SUMIFS(SAISIE!$G$2:$G$501,SAISIE!$D$2:$D$501,LISTES!$K$5)+SUMIFS(SAISIE!$H$2:$H$501,SAISIE!$D$2:$D$501,LISTES!$K$5)+SUMIFS(SAISIE!$I$2:$I$501,SAISIE!$D$2:$D$501,LISTES!$K$5)+SUMIFS(SAISIE!$J$2:$J$501,SAISIE!$D$2:$D$501,LISTES!$K$5)+SUMIFS(SAISIE!$K$2:$K$501,SAISIE!$D$2:$D$501,LISTES!$K$5)+SUMIFS(SAISIE!$L$2:$L$501,SAISIE!$D$2:$D$501,LISTES!$K$5)+SUMIFS(SAISIE!$M$2:$M$501,SAISIE!$D$2:$D$501,LISTES!$K$5)+SUMIFS(SAISIE!$N$2:$N$501,SAISIE!$D$2:$D$501,LISTES!$K$5)) | C6: =IFERROR(COUNTIFS(SAISIE!$D$2:$D$501,LISTES!$K$5),0) | D6: =IFERROR(SUMPRODUCT((SAISIE!$D$2:$D$501=LISTES!$K$5)*((SAISIE!$E$2:$E$501>0)+(SAISIE!$F$2:$F$501>0)+(SAISIE!$G$2:$G$501>0)+(SAISIE!$H$2:$H$501>0)+(SAISIE!$I$2:$I$501>0)+(SAISIE!$J$2:$J$501>0)+(SAISIE!$K$2:$K$501>0)+(SAISIE!$L$2:$L$501>0)+(SAISIE!$M$2:$M$501>0)+(SAISIE!$N$2:$N$501>0))),0) | E6: =IFERROR(SUMPRODUCT((SAISIE!$D$2:$D$501=LISTES!$K$5)/(COUNTIFS(SAISIE!$A$2:$A$501,SAISIE!$A$2:$A$501,SAISIE!$D$2:$D$501,LISTES!$K$5)+((SAISIE!$D$2:$D$501<>LISTES!$K$5)*1E9))),0)
A7: =LISTES!$K$6 | B7: =IF(LISTES!$K$6="",0,SUMIFS(SAISIE!$E$2:$E$501,SAISIE!$D$2:$D$501,LISTES!$K$6)+SUMIFS(SAISIE!$F$2:$F$501,SAISIE!$D$2:$D$501,LISTES!$K$6)+SUMIFS(SAISIE!$G$2:$G$501,SAISIE!$D$2:$D$501,LISTES!$K$6)+SUMIFS(SAISIE!$H$2:$H$501,SAISIE!$D$2:$D$501,LISTES!$K$6)+SUMIFS(SAISIE!$I$2:$I$501,SAISIE!$D$2:$D$501,LISTES!$K$6)+SUMIFS(SAISIE!$J$2:$J$501,SAISIE!$D$2:$D$501,LISTES!$K$6)+SUMIFS(SAISIE!$K$2:$K$501,SAISIE!$D$2:$D$501,LISTES!$K$6)+SUMIFS(SAISIE!$L$2:$L$501,SAISIE!$D$2:$D$501,LISTES!$K$6)+SUMIFS(SAISIE!$M$2:$M$501,SAISIE!$D$2:$D$501,LISTES!$K$6)+SUMIFS(SAISIE!$N$2:$N$501,SAISIE!$D$2:$D$501,LISTES!$K$6)) | C7: =IFERROR(COUNTIFS(SAISIE!$D$2:$D$501,LISTES!$K$6),0) | D7: =IFERROR(SUMPRODUCT((SAISIE!$D$2:$D$501=LISTES!$K$6)*((SAISIE!$E$2:$E$501>0)+(SAISIE!$F$2:$F$501>0)+(SAISIE!$G$2:$G$501>0)+(SAISIE!$H$2:$H$501>0)+(SAISIE!$I$2:$I$501>0)+(SAISIE!$J$2:$J$501>0)+(SAISIE!$K$2:$K$501>0)+(SAISIE!$L$2:$L$501>0)+(SAISIE!$M$2:$M$501>0)+(SAISIE!$N$2:$N$501>0))),0) | E7: =IFERROR(SUMPRODUCT((SAISIE!$D$2:$D$501=LISTES!$K$6)/(COUNTIFS(SAISIE!$A$2:$A$501,SAISIE!$A$2:$A$501,SAISIE!$D$2:$D$501,LISTES!$K$6)+((SAISIE!$D$2:$D$501<>LISTES!$K$6)*1E9))),0)
A8: =LISTES!$K$7 | B8: =IF(LISTES!$K$7="",0,SUMIFS(SAISIE!$E$2:$E$501,SAISIE!$D$2:$D$501,LISTES!$K$7)+SUMIFS(SAISIE!$F$2:$F$501,SAISIE!$D$2:$D$501,LISTES!$K$7)+SUMIFS(SAISIE!$G$2:$G$501,SAISIE!$D$2:$D$501,LISTES!$K$7)+SUMIFS(SAISIE!$H$2:$H$501,SAISIE!$D$2:$D$501,LISTES!$K$7)+SUMIFS(SAISIE!$I$2:$I$501,SAISIE!$D$2:$D$501,LISTES!$K$7)+SUMIFS(SAISIE!$J$2:$J$501,SAISIE!$D$2:$D$501,LISTES!$K$7)+SUMIFS(SAISIE!$K$2:$K$501,SAISIE!$D$2:$D$501,LISTES!$K$7)+SUMIFS(SAISIE!$L$2:$L$501,SAISIE!$D$2:$D$501,LISTES!$K$7)+SUMIFS(SAISIE!$M$2:$M$501,SAISIE!$D$2:$D$501,LISTES!$K$7)+SUMIFS(SAISIE!$N$2:$N$501,SAISIE!$D$2:$D$501,LISTES!$K$7)) | C8: =IFERROR(COUNTIFS(SAISIE!$D$2:$D$501,LISTES!$K$7),0) | D8: =IFERROR(SUMPRODUCT((SAISIE!$D$2:$D$501=LISTES!$K$7)*((SAISIE!$E$2:$E$501>0)+(SAISIE!$F$2:$F$501>0)+(SAISIE!$G$2:$G$501>0)+(SAISIE!$H$2:$H$501>0)+(SAISIE!$I$2:$I$501>0)+(SAISIE!$J$2:$J$501>0)+(SAISIE!$K$2:$K$501>0)+(SAISIE!$L$2:$L$501>0)+(SAISIE!$M$2:$M$501>0)+(SAISIE!$N$2:$N$501>0))),0) | E8: =IFERROR(SUMPRODUCT((SAISIE!$D$2:$D$501=LISTES!$K$7)/(COUNTIFS(SAISIE!$A$2:$A$501,SAISIE!$A$2:$A$501,SAISIE!$D$2:$D$501,LISTES!$K$7)+((SAISIE!$D$2:$D$501<>LISTES!$K$7)*1E9))),0)
A9: =LISTES!$K$8 | B9: =IF(LISTES!$K$8="",0,SUMIFS(SAISIE!$E$2:$E$501,SAISIE!$D$2:$D$501,LISTES!$K$8)+SUMIFS(SAISIE!$F$2:$F$501,SAISIE!$D$2:$D$501,LISTES!$K$8)+SUMIFS(SAISIE!$G$2:$G$501,SAISIE!$D$2:$D$501,LISTES!$K$8)+SUMIFS(SAISIE!$H$2:$H$501,SAISIE!$D$2:$D$501,LISTES!$K$8)+SUMIFS(SAISIE!$I$2:$I$501,SAISIE!$D$2:$D$501,LISTES!$K$8)+SUMIFS(SAISIE!$J$2:$J$501,SAISIE!$D$2:$D$501,LISTES!$K$8)+SUMIFS(SAISIE!$K$2:$K$501,SAISIE!$D$2:$D$501,LISTES!$K$8)+SUMIFS(SAISIE!$L$2:$L$501,SAISIE!$D$2:$D$501,LISTES!$K$8)+SUMIFS(SAISIE!$M$2:$M$501,SAISIE!$D$2:$D$501,LISTES!$K$8)+SUMIFS(SAISIE!$N$2:$N$501,SAISIE!$D$2:$D$501,LISTES!$K$8)) | C9: =IFERROR(COUNTIFS(SAISIE!$D$2:$D$501,LISTES!$K$8),0) | D9: =IFERROR(SUMPRODUCT((SAISIE!$D$2:$D$501=LISTES!$K$8)*((SAISIE!$E$2:$E$501>0)+(SAISIE!$F$2:$F$501>0)+(SAISIE!$G$2:$G$501>0)+(SAISIE!$H$2:$H$501>0)+(SAISIE!$I$2:$I$501>0)+(SAISIE!$J$2:$J$501>0)+(SAISIE!$K$2:$K$501>0)+(SAISIE!$L$2:$L$501>0)+(SAISIE!$M$2:$M$501>0)+(SAISIE!$N$2:$N$501>0))),0) | E9: =IFERROR(SUMPRODUCT((SAISIE!$D$2:$D$501=LISTES!$K$8)/(COUNTIFS(SAISIE!$A$2:$A$501,SAISIE!$A$2:$A$501,SAISIE!$D$2:$D$501,LISTES!$K$8)+((SAISIE!$D$2:$D$501<>LISTES!$K$8)*1E9))),0)
A10: =LISTES!$K$9 | B10: =IF(LISTES!$K$9="",0,SUMIFS(SAISIE!$E$2:$E$501,SAISIE!$D$2:$D$501,LISTES!$K$9)+SUMIFS(SAISIE!$F$2:$F$501,SAISIE!$D$2:$D$501,LISTES!$K$9)+SUMIFS(SAISIE!$G$2:$G$501,SAISIE!$D$2:$D$501,LISTES!$K$9)+SUMIFS(SAISIE!$H$2:$H$501,SAISIE!$D$2:$D$501,LISTES!$K$9)+SUMIFS(SAISIE!$I$2:$I$501,SAISIE!$D$2:$D$501,LISTES!$K$9)+SUMIFS(SAISIE!$J$2:$J$501,SAISIE!$D$2:$D$501,LISTES!$K$9)+SUMIFS(SAISIE!$K$2:$K$501,SAISIE!$D$2:$D$501,LISTES!$K$9)+SUMIFS(SAISIE!$L$2:$L$501,SAISIE!$D$2:$D$501,LISTES!$K$9)+SUMIFS(SAISIE!$M$2:$M$501,SAISIE!$D$2:$D$501,LISTES!$K$9)+SUMIFS(SAISIE!$N$2:$N$501,SAISIE!$D$2:$D$501,LISTES!$K$9)) | C10: =IFERROR(COUNTIFS(SAISIE!$D$2:$D$501,LISTES!$K$9),0) | D10: =IFERROR(SUMPRODUCT((SAISIE!$D$2:$D$501=LISTES!$K$9)*((SAISIE!$E$2:$E$501>0)+(SAISIE!$F$2:$F$501>0)+(SAISIE!$G$2:$G$501>0)+(SAISIE!$H$2:$H$501>0)+(SAISIE!$I$2:$I$501>0)+(SAISIE!$J$2:$J$501>0)+(SAISIE!$K$2:$K$501>0)+(SAISIE!$L$2:$L$501>0)+(SAISIE!$M$2:$M$501>0)+(SAISIE!$N$2:$N$501>0))),0) | E10: =IFERROR(SUMPRODUCT((SAISIE!$D$2:$D$501=LISTES!$K$9)/(COUNTIFS(SAISIE!$A$2:$A$501,SAISIE!$A$2:$A$501,SAISIE!$D$2:$D$501,LISTES!$K$9)+((SAISIE!$D$2:$D$501<>LISTES!$K$9)*1E9))),0)
A11: =LISTES!$K$10 | B11: =IF(LISTES!$K$10="",0,SUMIFS(SAISIE!$E$2:$E$501,SAISIE!$D$2:$D$501,LISTES!$K$10)+SUMIFS(SAISIE!$F$2:$F$501,SAISIE!$D$2:$D$501,LISTES!$K$10)+SUMIFS(SAISIE!$G$2:$G$501,SAISIE!$D$2:$D$501,LISTES!$K$10)+SUMIFS(SAISIE!$H$2:$H$501,SAISIE!$D$2:$D$501,LISTES!$K$10)+SUMIFS(SAISIE!$I$2:$I$501,SAISIE!$D$2:$D$501,LISTES!$K$10)+SUMIFS(SAISIE!$J$2:$J$501,SAISIE!$D$2:$D$501,LISTES!$K$10)+SUMIFS(SAISIE!$K$2:$K$501,SAISIE!$D$2:$D$501,LISTES!$K$10)+SUMIFS(SAISIE!$L$2:$L$501,SAISIE!$D$2:$D$501,LISTES!$K$10)+SUMIFS(SAISIE!$M$2:$M$501,SAISIE!$D$2:$D$501,LISTES!$K$10)+SUMIFS(SAISIE!$N$2:$N$501,SAISIE!$D$2:$D$501,LISTES!$K$10)) | C11: =IFERROR(COUNTIFS(SAISIE!$D$2:$D$501,LISTES!$K$10),0) | D11: =IFERROR(SUMPRODUCT((SAISIE!$D$2:$D$501=LISTES!$K$10)*((SAISIE!$E$2:$E$501>0)+(SAISIE!$F$2:$F$501>0)+(SAISIE!$G$2:$G$501>0)+(SAISIE!$H$2:$H$501>0)+(SAISIE!$I$2:$I$501>0)+(SAISIE!$J$2:$J$501>0)+(SAISIE!$K$2:$K$501>0)+(SAISIE!$L$2:$L$501>0)+(SAISIE!$M$2:$M$501>0)+(SAISIE!$N$2:$N$501>0))),0) | E11: =IFERROR(SUMPRODUCT((SAISIE!$D$2:$D$501=LISTES!$K$10)/(COUNTIFS(SAISIE!$A$2:$A$501,SAISIE!$A$2:$A$501,SAISIE!$D$2:$D$501,LISTES!$K$10)+((SAISIE!$D$2:$D$501<>LISTES!$K$10)*1E9))),0)
A12: =LISTES!$K$11 | B12: =IF(LISTES!$K$11="",0,SUMIFS(SAISIE!$E$2:$E$501,SAISIE!$D$2:$D$501,LISTES!$K$11)+SUMIFS(SAISIE!$F$2:$F$501,SAISIE!$D$2:$D$501,LISTES!$K$11)+SUMIFS(SAISIE!$G$2:$G$501,SAISIE!$D$2:$D$501,LISTES!$K$11)+SUMIFS(SAISIE!$H$2:$H$501,SAISIE!$D$2:$D$501,LISTES!$K$11)+SUMIFS(SAISIE!$I$2:$I$501,SAISIE!$D$2:$D$501,LISTES!$K$11)+SUMIFS(SAISIE!$J$2:$J$501,SAISIE!$D$2:$D$501,LISTES!$K$11)+SUMIFS(SAISIE!$K$2:$K$501,SAISIE!$D$2:$D$501,LISTES!$K$11)+SUMIFS(SAISIE!$L$2:$L$501,SAISIE!$D$2:$D$501,LISTES!$K$11)+SUMIFS(SAISIE!$M$2:$M$501,SAISIE!$D$2:$D$501,LISTES!$K$11)+SUMIFS(SAISIE!$N$2:$N$501,SAISIE!$D$2:$D$501,LISTES!$K$11)) | C12: =IFERROR(COUNTIFS(SAISIE!$D$2:$D$501,LISTES!$K$11),0) | D12: =IFERROR(SUMPRODUCT((SAISIE!$D$2:$D$501=LISTES!$K$11)*((SAISIE!$E$2:$E$501>0)+(SAISIE!$F$2:$F$501>0)+(SAISIE!$G$2:$G$501>0)+(SAISIE!$H$2:$H$501>0)+(SAISIE!$I$2:$I$501>0)+(SAISIE!$J$2:$J$501>0)+(SAISIE!$K$2:$K$501>0)+(SAISIE!$L$2:$L$501>0)+(SAISIE!$M$2:$M$501>0)+(SAISIE!$N$2:$N$501>0))),0) | E12: =IFERROR(SUMPRODUCT((SAISIE!$D$2:$D$501=LISTES!$K$11)/(COUNTIFS(SAISIE!$A$2:$A$501,SAISIE!$A$2:$A$501,SAISIE!$D$2:$D$501,LISTES!$K$11)+((SAISIE!$D$2:$D$501<>LISTES!$K$11)*1E9))),0)
A13: TOTAL | B13: =SUM(B3:B12) | C13: =SUM(C3:C12) | D13: =SUM(D3:D12) | E13: =SUM(E3:E12)

Sheet EQUIPE
A1: Intervenant | B1: =LISTES!$E$2 | C1: =LISTES!$E$3 | D1: =LISTES!$E$4 | E1: =LISTES!$E$5 | F1: =LISTES!$E$6 | G1: =LISTES!$E$7 | H1: =LISTES!$E$8 | I1: =LISTES!$E$9 | J1: =LISTES!$E$10 | K1: =LISTES!$E$11 | L1: =LISTES!$G$2 | M1: =LISTES!$G$3 | N1: =LISTES!$G$4 | O1: =LISTES!$G$5 | P1: =LISTES!$G$6 | Q1: =LISTES!$G$7 | R1: =LISTES!$G$8 | S1: =LISTES!$G$9 | T1: =LISTES!$G$10 | U1: =LISTES!$G$11 | V1: =LISTES!$I$2 | W1: =LISTES!$I$3 | X1: =LISTES!$I$4 | Y1: =LISTES!$I$5 | Z1: =LISTES!$I$6 | AA1: =LISTES!$I$7 | AB1: =LISTES!$I$8 | AC1: =LISTES!$I$9 | AD1: =LISTES!$I$10 | AE1: =LISTES!$I$11
A2: =LISTES!$A$2 | B2: =IF(LISTES!$E$2="",0,SUMIFS(SAISIE!$E$2:$E$501,SAISIE!$C$2:$C$501,LISTES!$E$2)) | C2: =IF(LISTES!$E$3="",0,SUMIFS(SAISIE!$E$2:$E$501,SAISIE!$C$2:$C$501,LISTES!$E$3)) | D2: =IF(LISTES!$E$4="",0,SUMIFS(SAISIE!$E$2:$E$501,SAISIE!$C$2:$C$501,LISTES!$E$4)) | E2: =IF(LISTES!$E$5="",0,SUMIFS(SAISIE!$E$2:$E$501,SAISIE!$C$2:$C$501,LISTES!$E$5)) | F2: =IF(LISTES!$E$6="",0,SUMIFS(SAISIE!$E$2:$E$501,SAISIE!$C$2:$C$501,LISTES!$E$6)) | G2: =IF(LISTES!$E$7="",0,SUMIFS(SAISIE!$E$2:$E$501,SAISIE!$C$2:$C$501,LISTES!$E$7)) | H2: =IF(LISTES!$E$8="",0,SUMIFS(SAISIE!$E$2:$E$501,SAISIE!$C$2:$C$501,LISTES!$E$8)) | I2: =IF(LISTES!$E$9="",0,SUMIFS(SAISIE!$E$2:$E$501,SAISIE!$C$2:$C$501,LISTES!$E$9)) | J2: =IF(LISTES!$E$10="",0,SUMIFS(SAISIE!$E$2:$E$501,SAISIE!$C$2:$C$501,LISTES!$E$10)) | K2: =IF(LISTES!$E$11="",0,SUMIFS(SAISIE!$E$2:$E$501,SAISIE!$C$2:$C$501,LISTES!$E$11)) | L2: =IF(LISTES!$G$2="",0,SUMIFS(SAISIE!$E$2:$E$501,SAISIE!$C$2:$C$501,LISTES!$G$2)) | M2: =IF(LISTES!$G$3="",0,SUMIFS(SAISIE!$E$2:$E$501,SAISIE!$C$2:$C$501,LISTES!$G$3)) | N2: =IF(LISTES!$G$4="",0,SUMIFS(SAISIE!$E$2:$E$501,SAISIE!$C$2:$C$501,LISTES!$G$4)) | O2: =IF(LISTES!$G$5="",0,SUMIFS(SAISIE!$E$2:$E$501,SAISIE!$C$2:$C$501,LISTES!$G$5)) | P2: =IF(LISTES!$G$6="",0,SUMIFS(SAISIE!$E$2:$E$501,SAISIE!$C$2:$C$501,LISTES!$G$6)) | Q2: =IF(LISTES!$G$7="",0,SUMIFS(SAISIE!$E$2:$E$501,SAISIE!$C$2:$C$501,LISTES!$G$7)) | R2: =IF(LISTES!$G$8="",0,SUMIFS(SAISIE!$E$2:$E$501,SAISIE!$C$2:$C$501,LISTES!$G$8)) | S2: =IF(LISTES!$G$9="",0,SUMIFS(SAISIE!$E$2:$E$501,SAISIE!$C$2:$C$501,LISTES!$G$9)) | T2: =IF(LISTES!$G$10="",0,SUMIFS(SAISIE!$E$2:$E$501,SAISIE!$C$2:$C$501,LISTES!$G$10)) | U2: =IF(LISTES!$G$11="",0,SUMIFS(SAISIE!$E$2:$E$501,SAISIE!$C$2:$C$501,LISTES!$G$11)) | V2: =IF(LISTES!$I$2="",0,SUMIFS(SAISIE!$E$2:$E$501,SAISIE!$C$2:$C$501,LISTES!$I$2)) | W2: =IF(LISTES!$I$3="",0,SUMIFS(SAISIE!$E$2:$E$501,SAISIE!$C$2:$C$501,LISTES!$I$3)) | X2: =IF(LISTES!$I$4="",0,SUMIFS(SAISIE!$E$2:$E$501,SAISIE!$C$2:$C$501,LISTES!$I$4)) | Y2: =IF(LISTES!$I$5="",0,SUMIFS(SAISIE!$E$2:$E$501,SAISIE!$C$2:$C$501,LISTES!$I$5)) | Z2: =IF(LISTES!$I$6="",0,SUMIFS(SAISIE!$E$2:$E$501,SAISIE!$C$2:$C$501,LISTES!$I$6)) | AA2: =IF(LISTES!$I$7="",0,SUMIFS(SAISIE!$E$2:$E$501,SAISIE!$C$2:$C$501,LISTES!$I$7)) | AB2: =IF(LISTES!$I$8="",0,SUMIFS(SAISIE!$E$2:$E$501,SAISIE!$C$2:$C$501,LISTES!$I$8)) | AC2: =IF(LISTES!$I$9="",0,SUMIFS(SAISIE!$E$2:$E$501,SAISIE!$C$2:$C$501,LISTES!$I$9)) | AD2: =IF(LISTES!$I$10="",0,SUMIFS(SAISIE!$E$2:$E$501,SAISIE!$C$2:$C$501,LISTES!$I$10)) | AE2: =IF(LISTES!$I$11="",0,SUMIFS(SAISIE!$E$2:$E$501,SAISIE!$C$2:$C$501,LISTES!$I$11))
A3: =LISTES!$A$3 | B3: =IF(LISTES!$E$2="",0,SUMIFS(SAISIE!$F$2:$F$501,SAISIE!$C$2:$C$501,LISTES!$E$2)) | C3: =IF(LISTES!$E$3="",0,SUMIFS(SAISIE!$F$2:$F$501,SAISIE!$C$2:$C$501,LISTES!$E$3)) | D3: =IF(LISTES!$E$4="",0,SUMIFS(SAISIE!$F$2:$F$501,SAISIE!$C$2:$C$501,LISTES!$E$4)) | E3: =IF(LISTES!$E$5="",0,SUMIFS(SAISIE!$F$2:$F$501,SAISIE!$C$2:$C$501,LISTES!$E$5)) | F3: =IF(LISTES!$E$6="",0,SUMIFS(SAISIE!$F$2:$F$501,SAISIE!$C$2:$C$501,LISTES!$E$6)) | G3: =IF(LISTES!$E$7="",0,SUMIFS(SAISIE!$F$2:$F$501,SAISIE!$C$2:$C$501,LISTES!$E$7)) | H3: =IF(LISTES!$E$8="",0,SUMIFS(SAISIE!$F$2:$F$501,SAISIE!$C$2:$C$501,LISTES!$E$8)) | I3: =IF(LISTES!$E$9="",0,SUMIFS(SAISIE!$F$2:$F$501,SAISIE!$C$2:$C$501,LISTES!$E$9)) | J3: =IF(LISTES!$E$10="",0,SUMIFS(SAISIE!$F$2:$F$501,SAISIE!$C$2:$C$501,LISTES!$E$10)) | K3: =IF(LISTES!$E$11="",0,SUMIFS(SAISIE!$F$2:$F$501,SAISIE!$C$2:$C$501,LISTES!$E$11)) | L3: =IF(LISTES!$G$2="",0,SUMIFS(SAISIE!$F$2:$F$501,SAISIE!$C$2:$C$501,LISTES!$G$2)) | M3: =IF(LISTES!$G$3="",0,SUMIFS(SAISIE!$F$2:$F$501,SAISIE!$C$2:$C$501,LISTES!$G$3)) | N3: =IF(LISTES!$G$4="",0,SUMIFS(SAISIE!$F$2:$F$501,SAISIE!$C$2:$C$501,LISTES!$G$4)) | O3: =IF(LISTES!$G$5="",0,SUMIFS(SAISIE!$F$2:$F$501,SAISIE!$C$2:$C$501,LISTES!$G$5)) | P3: =IF(LISTES!$G$6="",0,SUMIFS(SAISIE!$F$2:$F$501,SAISIE!$C$2:$C$501,LISTES!$G$6)) | Q3: =IF(LISTES!$G$7="",0,SUMIFS(SAISIE!$F$2:$F$501,SAISIE!$C$2:$C$501,LISTES!$G$7)) | R3: =IF(LISTES!$G$8="",0,SUMIFS(SAISIE!$F$2:$F$501,SAISIE!$C$2:$C$501,LISTES!$G$8)) | S3: =IF(LISTES!$G$9="",0,SUMIFS(SAISIE!$F$2:$F$501,SAISIE!$C$2:$C$501,LISTES!$G$9)) | T3: =IF(LISTES!$G$10="",0,SUMIFS(SAISIE!$F$2:$F$501,SAISIE!$C$2:$C$501,LISTES!$G$10)) | U3: =IF(LISTES!$G$11="",0,SUMIFS(SAISIE!$F$2:$F$501,SAISIE!$C$2:$C$501,LISTES!$G$11)) | V3: =IF(LISTES!$I$2="",0,SUMIFS(SAISIE!$F$2:$F$501,SAISIE!$C$2:$C$501,LISTES!$I$2)) | W3: =IF(LISTES!$I$3="",0,SUMIFS(SAISIE!$F$2:$F$501,SAISIE!$C$2:$C$501,LISTES!$I$3)) | X3: =IF(LISTES!$I$4="",0,SUMIFS(SAISIE!$F$2:$F$501,SAISIE!$C$2:$C$501,LISTES!$I$4)) | Y3: =IF(LISTES!$I$5="",0,SUMIFS(SAISIE!$F$2:$F$501,SAISIE!$C$2:$C$501,LISTES!$I$5)) | Z3: =IF(LISTES!$I$6="",0,SUMIFS(SAISIE!$F$2:$F$501,SAISIE!$C$2:$C$501,LISTES!$I$6)) | AA3: =IF(LISTES!$I$7="",0,SUMIFS(SAISIE!$F$2:$F$501,SAISIE!$C$2:$C$501,LISTES!$I$7)) | AB3: =IF(LISTES!$I$8="",0,SUMIFS(SAISIE!$F$2:$F$501,SAISIE!$C$2:$C$501,LISTES!$I$8)) | AC3: =IF(LISTES!$I$9="",0,SUMIFS(SAISIE!$F$2:$F$501,SAISIE!$C$2:$C$501,LISTES!$I$9)) | AD3: =IF(LISTES!$I$10="",0,SUMIFS(SAISIE!$F$2:$F$501,SAISIE!$C$2:$C$501,LISTES!$I$10)) | AE3: =IF(LISTES!$I$11="",0,SUMIFS(SAISIE!$F$2:$F$501,SAISIE!$C$2:$C$501,LISTES!$I$11))
A4: =LISTES!$A$4 | B4: =IF(LISTES!$E$2="",0,SUMIFS(SAISIE!$G$2:$G$501,SAISIE!$C$2:$C$501,LISTES!$E$2)) | C4: =IF(LISTES!$E$3="",0,SUMIFS(SAISIE!$G$2:$G$501,SAISIE!$C$2:$C$501,LISTES!$E$3)) | D4: =IF(LISTES!$E$4="",0,SUMIFS(SAISIE!$G$2:$G$501,SAISIE!$C$2:$C$501,LISTES!$E$4)) | E4: =IF(LISTES!$E$5="",0,SUMIFS(SAISIE!$G$2:$G$501,SAISIE!$C$2:$C$501,LISTES!$E$5)) | F4: =IF(LISTES!$E$6="",0,SUMIFS(SAISIE!$G$2:$G$501,SAISIE!$C$2:$C$501,LISTES!$E$6)) | G4: =IF(LISTES!$E$7="",0,SUMIFS(SAISIE!$G$2:$G$501,SAISIE!$C$2:$C$501,LISTES!$E$7)) | H4: =IF(LISTES!$E$8="",0,SUMIFS(SAISIE!$G$2:$G$501,SAISIE!$C$2:$C$501,LISTES!$E$8)) | I4: =IF(LISTES!$E$9="",0,SUMIFS(SAISIE!$G$2:$G$501,SAISIE!$C$2:$C$501,LISTES!$E$9)) | J4: =IF(LISTES!$E$10="",0,SUMIFS(SAISIE!$G$2:$G$501,SAISIE!$C$2:$C$501,LISTES!$E$10)) | K4: =IF(LISTES!$E$11="",0,SUMIFS(SAISIE!$G$2:$G$501,SAISIE!$C$2:$C$501,LISTES!$E$11)) | L4: =IF(LISTES!$G$2="",0,SUMIFS(SAISIE!$G$2:$G$501,SAISIE!$C$2:$C$501,LISTES!$G$2)) | M4: =IF(LISTES!$G$3="",0,SUMIFS(SAISIE!$G$2:$G$501,SAISIE!$C$2:$C$501,LISTES!$G$3)) | N4: =IF(LISTES!$G$4="",0,SUMIFS(SAISIE!$G$2:$G$501,SAISIE!$C$2:$C$501,LISTES!$G$4)) | O4: =IF(LISTES!$G$5="",0,SUMIFS(SAISIE!$G$2:$G$501,SAISIE!$C$2:$C$501,LISTES!$G$5)) | P4: =IF(LISTES!$G$6="",0,SUMIFS(SAISIE!$G$2:$G$501,SAISIE!$C$2:$C$501,LISTES!$G$6)) | Q4: =IF(LISTES!$G$7="",0,SUMIFS(SAISIE!$G$2:$G$501,SAISIE!$C$2:$C$501,LISTES!$G$7)) | R4: =IF(LISTES!$G$8="",0,SUMIFS(SAISIE!$G$2:$G$501,SAISIE!$C$2:$C$501,LISTES!$G$8)) | S4: =IF(LISTES!$G$9="",0,SUMIFS(SAISIE!$G$2:$G$501,SAISIE!$C$2:$C$501,LISTES!$G$9)) | T4: =IF(LISTES!$G$10="",0,SUMIFS(SAISIE!$G$2:$G$501,SAISIE!$C$2:$C$501,LISTES!$G$10)) | U4: =IF(LISTES!$G$11="",0,SUMIFS(SAISIE!$G$2:$G$501,SAISIE!$C$2:$C$501,LISTES!$G$11)) | V4: =IF(LISTES!$I$2="",0,SUMIFS(SAISIE!$G$2:$G$501,SAISIE!$C$2:$C$501,LISTES!$I$2)) | W4: =IF(LISTES!$I$3="",0,SUMIFS(SAISIE!$G$2:$G$501,SAISIE!$C$2:$C$501,LISTES!$I$3)) | X4: =IF(LISTES!$I$4="",0,SUMIFS(SAISIE!$G$2:$G$501,SAISIE!$C$2:$C$501,LISTES!$I$4)) | Y4: =IF(LISTES!$I$5="",0,SUMIFS(SAISIE!$G$2:$G$501,SAISIE!$C$2:$C$501,LISTES!$I$5)) | Z4: =IF(LISTES!$I$6="",0,SUMIFS(SAISIE!$G$2:$G$501,SAISIE!$C$2:$C$501,LISTES!$I$6)) | AA4: =IF(LISTES!$I$7="",0,SUMIFS(SAISIE!$G$2:$G$501,SAISIE!$C$2:$C$501,LISTES!$I$7)) | AB4: =IF(LISTES!$I$8="",0,SUMIFS(SAISIE!$G$2:$G$501,SAISIE!$C$2:$C$501,LISTES!$I$8)) | AC4: =IF(LISTES!$I$9="",0,SUMIFS(SAISIE!$G$2:$G$501,SAISIE!$C$2:$C$501,LISTES!$I$9)) | AD4: =IF(LISTES!$I$10="",0,SUMIFS(SAISIE!$G$2:$G$501,SAISIE!$C$2:$C$501,LISTES!$I$10)) | AE4: =IF(LISTES!$I$11="",0,SUMIFS(SAISIE!$G$2:$G$501,SAISIE!$C$2:$C$501,LISTES!$I$11))
A5: =LISTES!$A$5 | B5: =IF(LISTES!$E$2="",0,SUMIFS(SAISIE!$H$2:$H$501,SAISIE!$C$2:$C$501,LISTES!$E$2)) | C5: =IF(LISTES!$E$3="",0,SUMIFS(SAISIE!$H$2:$H$501,SAISIE!$C$2:$C$501,LISTES!$E$3)) | D5: =IF(LISTES!$E$4="",0,SUMIFS(SAISIE!$H$2:$H$501,SAISIE!$C$2:$C$501,LISTES!$E$4)) | E5: =IF(LISTES!$E$5="",0,SUMIFS(SAISIE!$H$2:$H$501,SAISIE!$C$2:$C$501,LISTES!$E$5)) | F5: =IF(LISTES!$E$6="",0,SUMIFS(SAISIE!$H$2:$H$501,SAISIE!$C$2:$C$501,LISTES!$E$6)) | G5: =IF(LISTES!$E$7="",0,SUMIFS(SAISIE!$H$2:$H$501,SAISIE!$C$2:$C$501,LISTES!$E$7)) | H5: =IF(LISTES!$E$8="",0,SUMIFS(SAISIE!$H$2:$H$501,SAISIE!$C$2:$C$501,LISTES!$E$8)) | I5: =IF(LISTES!$E$9="",0,SUMIFS(SAISIE!$H$2:$H$501,SAISIE!$C$2:$C$501,LISTES!$E$9)) | J5: =IF(LISTES!$E$10="",0,SUMIFS(SAISIE!$H$2:$H$501,SAISIE!$C$2:$C$501,LISTES!$E$10)) | K5: =IF(LISTES!$E$11="",0,SUMIFS(SAISIE!$H$2:$H$501,SAISIE!$C$2:$C$501,LISTES!$E$11)) | L5: =IF(LISTES!$G$2="",0,SUMIFS(SAISIE!$H$2:$H$501,SAISIE!$C$2:$C$501,LISTES!$G$2)) | M5: =IF(LISTES!$G$3="",0,SUMIFS(SAISIE!$H$2:$H$501,SAISIE!$C$2:$C$501,LISTES!$G$3)) | N5: =IF(LISTES!$G$4="",0,SUMIFS(SAISIE!$H$2:$H$501,SAISIE!$C$2:$C$501,LISTES!$G$4)) | O5: =IF(LISTES!$G$5="",0,SUMIFS(SAISIE!$H$2:$H$501,SAISIE!$C$2:$C$501,LISTES!$G$5)) | P5: =IF(LISTES!$G$6="",0,SUMIFS(SAISIE!$H$2:$H$501,SAISIE!$C$2:$C$501,LISTES!$G$6)) | Q5: =IF(LISTES!$G$7="",0,SUMIFS(SAISIE!$H$2:$H$501,SAISIE!$C$2:$C$501,LISTES!$G$7)) | R5: =IF(LISTES!$G$8="",0,SUMIFS(SAISIE!$H$2:$H$501,SAISIE!$C$2:$C$501,LISTES!$G$8)) | S5: =IF(LISTES!$G$9="",0,SUMIFS(SAISIE!$H$2:$H$501,SAISIE!$C$2:$C$501,LISTES!$G$9)) | T5: =IF(LISTES!$G$10="",0,SUMIFS(SAISIE!$H$2:$H$501,SAISIE!$C$2:$C$501,LISTES!$G$10)) | U5: =IF(LISTES!$G$11="",0,SUMIFS(SAISIE!$H$2:$H$501,SAISIE!$C$2:$C$501,LISTES!$G$11)) | V5: =IF(LISTES!$I$2="",0,SUMIFS(SAISIE!$H$2:$H$501,SAISIE!$C$2:$C$501,LISTES!$I$2)) | W5: =IF(LISTES!$I$3="",0,SUMIFS(SAISIE!$H$2:$H$501,SAISIE!$C$2:$C$501,LISTES!$I$3)) | X5: =IF(LISTES!$I$4="",0,SUMIFS(SAISIE!$H$2:$H$501,SAISIE!$C$2:$C$501,LISTES!$I$4)) | Y5: =IF(LISTES!$I$5="",0,SUMIFS(SAISIE!$H$2:$H$501,SAISIE!$C$2:$C$501,LISTES!$I$5)) | Z5: =IF(LISTES!$I$6="",0,SUMIFS(SAISIE!$H$2:$H$501,SAISIE!$C$2:$C$501,LISTES!$I$6)) | AA5: =IF(LISTES!$I$7="",0,SUMIFS(SAISIE!$H$2:$H$501,SAISIE!$C$2:$C$501,LISTES!$I$7)) | AB5: =IF(LISTES!$I$8="",0,SUMIFS(SAISIE!$H$2:$H$501,SAISIE!$C$2:$C$501,LISTES!$I$8)) | AC5: =IF(LISTES!$I$9="",0,SUMIFS(SAISIE!$H$2:$H$501,SAISIE!$C$2:$C$501,LISTES!$I$9)) | AD5: =IF(LISTES!$I$10="",0,SUMIFS(SAISIE!$H$2:$H$501,SAISIE!$C$2:$C$501,LISTES!$I$10)) | AE5: =IF(LISTES!$I$11="",0,SUMIFS(SAISIE!$H$2:$H$501,SAISIE!$C$2:$C$501,LISTES!$I$11))
A6: =LISTES!$A$6 | B6: =IF(LISTES!$E$2="",0,SUMIFS(SAISIE!$I$2:$I$501,SAISIE!$C$2:$C$501,LISTES!$E$2)) | C6: =IF(LISTES!$E$3="",0,SUMIFS(SAISIE!$I$2:$I$501,SAISIE!$C$2:$C$501,LISTES!$E$3)) | D6: =IF(LISTES!$E$4="",0,SUMIFS(SAISIE!$I$2:$I$501,SAISIE!$C$2:$C$501,LISTES!$E$4)) | E6: =IF(LISTES!$E$5="",0,SUMIFS(SAISIE!$I$2:$I$501,SAISIE!$C$2:$C$501,LISTES!$E$5)) | F6: =IF(LISTES!$E$6="",0,SUMIFS(SAISIE!$I$2:$I$501,SAISIE!$C$2:$C$501,LISTES!$E$6)) | G6: =IF(LISTES!$E$7="",0,SUMIFS(SAISIE!$I$2:$I$501,SAISIE!$C$2:$C$501,LISTES!$E$7)) | H6: =IF(LISTES!$E$8="",0,SUMIFS(SAISIE!$I$2:$I$501,SAISIE!$C$2:$C$501,LISTES!$E$8)) | I6: =IF(LISTES!$E$9="",0,SUMIFS(SAISIE!$I$2:$I$501,SAISIE!$C$2:$C$501,LISTES!$E$9)) | J6: =IF(LISTES!$E$10="",0,SUMIFS(SAISIE!$I$2:$I$501,SAISIE!$C$2:$C$501,LISTES!$E$10)) | K6: =IF(LISTES!$E$11="",0,SUMIFS(SAISIE!$I$2:$I$501,SAISIE!$C$2:$C$501,LISTES!$E$11)) | L6: =IF(LISTES!$G$2="",0,SUMIFS(SAISIE!$I$2:$I$501,SAISIE!$C$2:$C$501,LISTES!$G$2)) | M6: =IF(LISTES!$G$3="",0,SUMIFS(SAISIE!$I$2:$I$501,SAISIE!$C$2:$C$501,LISTES!$G$3)) | N6: =IF(LISTES!$G$4="",0,SUMIFS(SAISIE!$I$2:$I$501,SAISIE!$C$2:$C$501,LISTES!$G$4)) | O6: =IF(LISTES!$G$5="",0,SUMIFS(SAISIE!$I$2:$I$501,SAISIE!$C$2:$C$501,LISTES!$G$5)) | P6: =IF(LISTES!$G$6="",0,SUMIFS(SAISIE!$I$2:$I$501,SAISIE!$C$2:$C$501,LISTES!$G$6)) | Q6: =IF(LISTES!$G$7="",0,SUMIFS(SAISIE!$I$2:$I$501,SAISIE!$C$2:$C$501,LISTES!$G$7)) | R6: =IF(LISTES!$G$8="",0,SUMIFS(SAISIE!$I$2:$I$501,SAISIE!$C$2:$C$501,LISTES!$G$8)) | S6: =IF(LISTES!$G$9="",0,SUMIFS(SAISIE!$I$2:$I$501,SAISIE!$C$2:$C$501,LISTES!$G$9)) | T6: =IF(LISTES!$G$10="",0,SUMIFS(SAISIE!$I$2:$I$501,SAISIE!$C$2:$C$501,LISTES!$G$10)) | U6: =IF(LISTES!$G$11="",0,SUMIFS(SAISIE!$I$2:$I$501,SAISIE!$C$2:$C$501,LISTES!$G$11)) | V6: =IF(LISTES!$I$2="",0,SUMIFS(SAISIE!$I$2:$I$501,SAISIE!$C$2:$C$501,LISTES!$I$2)) | W6: =IF(LISTES!$I$3="",0,SUMIFS(SAISIE!$I$2:$I$501,SAISIE!$C$2:$C$501,LISTES!$I$3)) | X6: =IF(LISTES!$I$4="",0,SUMIFS(SAISIE!$I$2:$I$501,SAISIE!$C$2:$C$501,LISTES!$I$4)) | Y6: =IF(LISTES!$I$5="",0,SUMIFS(SAISIE!$I$2:$I$501,SAISIE!$C$2:$C$501,LISTES!$I$5)) | Z6: =IF(LISTES!$I$6="",0,SUMIFS(SAISIE!$I$2:$I$501,SAISIE!$C$2:$C$501,LISTES!$I$6)) | AA6: =IF(LISTES!$I$7="",0,SUMIFS(SAISIE!$I$2:$I$501,SAISIE!$C$2:$C$501,LISTES!$I$7)) | AB6: =IF(LISTES!$I$8="",0,SUMIFS(SAISIE!$I$2:$I$501,SAISIE!$C$2:$C$501,LISTES!$I$8)) | AC6: =IF(LISTES!$I$9="",0,SUMIFS(SAISIE!$I$2:$I$501,SAISIE!$C$2:$C$501,LISTES!$I$9)) | AD6: =IF(LISTES!$I$10="",0,SUMIFS(SAISIE!$I$2:$I$501,SAISIE!$C$2:$C$501,LISTES!$I$10)) | AE6: =IF(LISTES!$I$11="",0,SUMIFS(SAISIE!$I$2:$I$501,SAISIE!$C$2:$C$501,LISTES!$I$11))
A7: =LISTES!$A$7 | B7: =IF(LISTES!$E$2="",0,SUMIFS(SAISIE!$J$2:$J$501,SAISIE!$C$2:$C$501,LISTES!$E$2)) | C7: =IF(LISTES!$E$3="",0,SUMIFS(SAISIE!$J$2:$J$501,SAISIE!$C$2:$C$501,LISTES!$E$3)) | D7: =IF(LISTES!$E$4="",0,SUMIFS(SAISIE!$J$2:$J$501,SAISIE!$C$2:$C$501,LISTES!$E$4)) | E7: =IF(LISTES!$E$5="",0,SUMIFS(SAISIE!$J$2:$J$501,SAISIE!$C$2:$C$501,LISTES!$E$5)) | F7: =IF(LISTES!$E$6="",0,SUMIFS(SAISIE!$J$2:$J$501,SAISIE!$C$2:$C$501,LISTES!$E$6)) | G7: =IF(LISTES!$E$7="",0,SUMIFS(SAISIE!$J$2:$J$501,SAISIE!$C$2:$C$501,LISTES!$E$7)) | H7: =IF(LISTES!$E$8="",0,SUMIFS(SAISIE!$J$2:$J$501,SAISIE!$C$2:$C$501,LISTES!$E$8)) | I7: =IF(LISTES!$E$9="",0,SUMIFS(SAISIE!$J$2:$J$501,SAISIE!$C$2:$C$501,LISTES!$E$9)) | J7: =IF(LISTES!$E$10="",0,SUMIFS(SAISIE!$J$2:$J$501,SAISIE!$C$2:$C$501,LISTES!$E$10)) | K7: =IF(LISTES!$E$11="",0,SUMIFS(SAISIE!$J$2:$J$501,SAISIE!$C$2:$C$501,LISTES!$E$11)) | L7: =IF(LISTES!$G$2="",0,SUMIFS(SAISIE!$J$2:$J$501,SAISIE!$C$2:$C$501,LISTES!$G$2)) | M7: =IF(LISTES!$G$3="",0,SUMIFS(SAISIE!$J$2:$J$501,SAISIE!$C$2:$C$501,LISTES!$G$3)) | N7: =IF(LISTES!$G$4="",0,SUMIFS(SAISIE!$J$2:$J$501,SAISIE!$C$2:$C$501,LISTES!$G$4)) | O7: =IF(LISTES!$G$5="",0,SUMIFS(SAISIE!$J$2:$J$501,SAISIE!$C$2:$C$501,LISTES!$G$5)) | P7: =IF(LISTES!$G$6="",0,SUMIFS(SAISIE!$J$2:$J$501,SAISIE!$C$2:$C$501,LISTES!$G$6)) | Q7: =IF(LISTES!$G$7="",0,SUMIFS(SAISIE!$J$2:$J$501,SAISIE!$C$2:$C$501,LISTES!$G$7)) | R7: =IF(LISTES!$G$8="",0,SUMIFS(SAISIE!$J$2:$J$501,SAISIE!$C$2:$C$501,LISTES!$G$8)) | S7: =IF(LISTES!$G$9="",0,SUMIFS(SAISIE!$J$2:$J$501,SAISIE!$C$2:$C$501,LISTES!$G$9)) | T7: =IF(LISTES!$G$10="",0,SUMIFS(SAISIE!$J$2:$J$501,SAISIE!$C$2:$C$501,LISTES!$G$10)) | U7: =IF(LISTES!$G$11="",0,SUMIFS(SAISIE!$J$2:$J$501,SAISIE!$C$2:$C$501,LISTES!$G$11)) | V7: =IF(LISTES!$I$2="",0,SUMIFS(SAISIE!$J$2:$J$501,SAISIE!$C$2:$C$501,LISTES!$I$2)) | W7: =IF(LISTES!$I$3="",0,SUMIFS(SAISIE!$J$2:$J$501,SAISIE!$C$2:$C$501,LISTES!$I$3)) | X7: =IF(LISTES!$I$4="",0,SUMIFS(SAISIE!$J$2:$J$501,SAISIE!$C$2:$C$501,LISTES!$I$4)) | Y7: =IF(LISTES!$I$5="",0,SUMIFS(SAISIE!$J$2:$J$501,SAISIE!$C$2:$C$501,LISTES!$I$5)) | Z7: =IF(LISTES!$I$6="",0,SUMIFS(SAISIE!$J$2:$J$501,SAISIE!$C$2:$C$501,LISTES!$I$6)) | AA7: =IF(LISTES!$I$7="",0,SUMIFS(SAISIE!$J$2:$J$501,SAISIE!$C$2:$C$501,LISTES!$I$7)) | AB7: =IF(LISTES!$I$8="",0,SUMIFS(SAISIE!$J$2:$J$501,SAISIE!$C$2:$C$501,LISTES!$I$8)) | AC7: =IF(LISTES!$I$9="",0,SUMIFS(SAISIE!$J$2:$J$501,SAISIE!$C$2:$C$501,LISTES!$I$9)) | AD7: =IF(LISTES!$I$10="",0,SUMIFS(SAISIE!$J$2:$J$501,SAISIE!$C$2:$C$501,LISTES!$I$10)) | AE7: =IF(LISTES!$I$11="",0,SUMIFS(SAISIE!$J$2:$J$501,SAISIE!$C$2:$C$501,LISTES!$I$11))
A8: =LISTES!$A$8 | B8: =IF(LISTES!$E$2="",0,SUMIFS(SAISIE!$K$2:$K$501,SAISIE!$C$2:$C$501,LISTES!$E$2)) | C8: =IF(LISTES!$E$3="",0,SUMIFS(SAISIE!$K$2:$K$501,SAISIE!$C$2:$C$501,LISTES!$E$3)) | D8: =IF(LISTES!$E$4="",0,SUMIFS(SAISIE!$K$2:$K$501,SAISIE!$C$2:$C$501,LISTES!$E$4)) | E8: =IF(LISTES!$E$5="",0,SUMIFS(SAISIE!$K$2:$K$501,SAISIE!$C$2:$C$501,LISTES!$E$5)) | F8: =IF(LISTES!$E$6="",0,SUMIFS(SAISIE!$K$2:$K$501,SAISIE!$C$2:$C$501,LISTES!$E$6)) | G8: =IF(LISTES!$E$7="",0,SUMIFS(SAISIE!$K$2:$K$501,SAISIE!$C$2:$C$501,LISTES!$E$7)) | H8: =IF(LISTES!$E$8="",0,SUMIFS(SAISIE!$K$2:$K$501,SAISIE!$C$2:$C$501,LISTES!$E$8)) | I8: =IF(LISTES!$E$9="",0,SUMIFS(SAISIE!$K$2:$K$501,SAISIE!$C$2:$C$501,LISTES!$E$9)) | J8: =IF(LISTES!$E$10="",0,SUMIFS(SAISIE!$K$2:$K$501,SAISIE!$C$2:$C$501,LISTES!$E$10)) | K8: =IF(LISTES!$E$11="",0,SUMIFS(SAISIE!$K$2:$K$501,SAISIE!$C$2:$C$501,LISTES!$E$11)) | L8: =IF(LISTES!$G$2="",0,SUMIFS(SAISIE!$K$2:$K$501,SAISIE!$C$2:$C$501,LISTES!$G$2)) | M8: =IF(LISTES!$G$3="",0,SUMIFS(SAISIE!$K$2:$K$501,SAISIE!$C$2:$C$501,LISTES!$G$3)) | N8: =IF(LISTES!$G$4="",0,SUMIFS(SAISIE!$K$2:$K$501,SAISIE!$C$2:$C$501,LISTES!$G$4)) | O8: =IF(LISTES!$G$5="",0,SUMIFS(SAISIE!$K$2:$K$501,SAISIE!$C$2:$C$501,LISTES!$G$5)) | P8: =IF(LISTES!$G$6="",0,SUMIFS(SAISIE!$K$2:$K$501,SAISIE!$C$2:$C$501,LISTES!$G$6)) | Q8: =IF(LISTES!$G$7="",0,SUMIFS(SAISIE!$K$2:$K$501,SAISIE!$C$2:$C$501,LISTES!$G$7)) | R8: =IF(LISTES!$G$8="",0,SUMIFS(SAISIE!$K$2:$K$501,SAISIE!$C$2:$C$501,LISTES!$G$8)) | S8: =IF(LISTES!$G$9="",0,SUMIFS(SAISIE!$K$2:$K$501,SAISIE!$C$2:$C$501,LISTES!$G$9)) | T8: =IF(LISTES!$G$10="",0,SUMIFS(SAISIE!$K$2:$K$501,SAISIE!$C$2:$C$501,LISTES!$G$10)) | U8: =IF(LISTES!$G$11="",0,SUMIFS(SAISIE!$K$2:$K$501,SAISIE!$C$2:$C$501,LISTES!$G$11)) | V8: =IF(LISTES!$I$2="",0,SUMIFS(SAISIE!$K$2:$K$501,SAISIE!$C$2:$C$501,LISTES!$I$2)) | W8: =IF(LISTES!$I$3="",0,SUMIFS(SAISIE!$K$2:$K$501,SAISIE!$C$2:$C$501,LISTES!$I$3)) | X8: =IF(LISTES!$I$4="",0,SUMIFS(SAISIE!$K$2:$K$501,SAISIE!$C$2:$C$501,LISTES!$I$4)) | Y8: =IF(LISTES!$I$5="",0,SUMIFS(SAISIE!$K$2:$K$501,SAISIE!$C$2:$C$501,LISTES!$I$5)) | Z8: =IF(LISTES!$I$6="",0,SUMIFS(SAISIE!$K$2:$K$501,SAISIE!$C$2:$C$501,LISTES!$I$6)) | AA8: =IF(LISTES!$I$7="",0,SUMIFS(SAISIE!$K$2:$K$501,SAISIE!$C$2:$C$501,LISTES!$I$7)) | AB8: =IF(LISTES!$I$8="",0,SUMIFS(SAISIE!$K$2:$K$501,SAISIE!$C$2:$C$501,LISTES!$I$8)) | AC8: =IF(LISTES!$I$9="",0,SUMIFS(SAISIE!$K$2:$K$501,SAISIE!$C$2:$C$501,LISTES!$I$9)) | AD8: =IF(LISTES!$I$10="",0,SUMIFS(SAISIE!$K$2:$K$501,SAISIE!$C$2:$C$501,LISTES!$I$10)) | AE8: =IF(LISTES!$I$11="",0,SUMIFS(SAISIE!$K$2:$K$501,SAISIE!$C$2:$C$501,LISTES!$I$11))
A9: =LISTES!$A$9 | B9: =IF(LISTES!$E$2="",0,SUMIFS(SAISIE!$L$2:$L$501,SAISIE!$C$2:$C$501,LISTES!$E$2)) | C9: =IF(LISTES!$E$3="",0,SUMIFS(SAISIE!$L$2:$L$501,SAISIE!$C$2:$C$501,LISTES!$E$3)) | D9: =IF(LISTES!$E$4="",0,SUMIFS(SAISIE!$L$2:$L$501,SAISIE!$C$2:$C$501,LISTES!$E$4)) | E9: =IF(LISTES!$E$5="",0,SUMIFS(SAISIE!$L$2:$L$501,SAISIE!$C$2:$C$501,LISTES!$E$5)) | F9: =IF(LISTES!$E$6="",0,SUMIFS(SAISIE!$L$2:$L$501,SAISIE!$C$2:$C$501,LISTES!$E$6)) | G9: =IF(LISTES!$E$7="",0,SUMIFS(SAISIE!$L$2:$L$501,SAISIE!$C$2:$C$501,LISTES!$E$7)) | H9: =IF(LISTES!$E$8="",0,SUMIFS(SAISIE!$L$2:$L$501,SAISIE!$C$2:$C$501,LISTES!$E$8)) | I9: =IF(LISTES!$E$9="",0,SUMIFS(SAISIE!$L$2:$L$501,SAISIE!$C$2:$C$501,LISTES!$E$9)) | J9: =IF(LISTES!$E$10="",0,SUMIFS(SAISIE!$L$2:$L$501,SAISIE!$C$2:$C$501,LISTES!$E$10)) | K9: =IF(LISTES!$E$11="",0,SUMIFS(SAISIE!$L$2:$L$501,SAISIE!$C$2:$C$501,LISTES!$E$11)) | L9: =IF(LISTES!$G$2="",0,SUMIFS(SAISIE!$L$2:$L$501,SAISIE!$C$2:$C$501,LISTES!$G$2)) | M9: =IF(LISTES!$G$3="",0,SUMIFS(SAISIE!$L$2:$L$501,SAISIE!$C$2:$C$501,LISTES!$G$3)) | N9: =IF(LISTES!$G$4="",0,SUMIFS(SAISIE!$L$2:$L$501,SAISIE!$C$2:$C$501,LISTES!$G$4)) | O9: =IF(LISTES!$G$5="",0,SUMIFS(SAISIE!$L$2:$L$501,SAISIE!$C$2:$C$501,LISTES!$G$5)) | P9: =IF(LISTES!$G$6="",0,SUMIFS(SAISIE!$L$2:$L$501,SAISIE!$C$2:$C$501,LISTES!$G$6)) | Q9: =IF(LISTES!$G$7="",0,SUMIFS(SAISIE!$L$2:$L$501,SAISIE!$C$2:$C$501,LISTES!$G$7)) | R9: =IF(LISTES!$G$8="",0,SUMIFS(SAISIE!$L$2:$L$501,SAISIE!$C$2:$C$501,LISTES!$G$8)) | S9: =IF(LISTES!$G$9="",0,SUMIFS(SAISIE!$L$2:$L$501,SAISIE!$C$2:$C$501,LISTES!$G$9)) | T9: =IF(LISTES!$G$10="",0,SUMIFS(SAISIE!$L$2:$L$501,SAISIE!$C$2:$C$501,LISTES!$G$10)) | U9: =IF(LISTES!$G$11="",0,SUMIFS(SAISIE!$L$2:$L$501,SAISIE!$C$2:$C$501,LISTES!$G$11)) | V9: =IF(LISTES!$I$2="",0,SUMIFS(SAISIE!$L$2:$L$501,SAISIE!$C$2:$C$501,LISTES!$I$2)) | W9: =IF(LISTES!$I$3="",0,SUMIFS(SAISIE!$L$2:$L$501,SAISIE!$C$2:$C$501,LISTES!$I$3)) | X9: =IF(LISTES!$I$4="",0,SUMIFS(SAISIE!$L$2:$L$501,SAISIE!$C$2:$C$501,LISTES!$I$4)) | Y9: =IF(LISTES!$I$5="",0,SUMIFS(SAISIE!$L$2:$L$501,SAISIE!$C$2:$C$501,LISTES!$I$5)) | Z9: =IF(LISTES!$I$6="",0,SUMIFS(SAISIE!$L$2:$L$501,SAISIE!$C$2:$C$501,LISTES!$I$6)) | AA9: =IF(LISTES!$I$7="",0,SUMIFS(SAISIE!$L$2:$L$501,SAISIE!$C$2:$C$501,LISTES!$I$7)) | AB9: =IF(LISTES!$I$8="",0,SUMIFS(SAISIE!$L$2:$L$501,SAISIE!$C$2:$C$501,LISTES!$I$8)) | AC9: =IF(LISTES!$I$9="",0,SUMIFS(SAISIE!$L$2:$L$501,SAISIE!$C$2:$C$501,LISTES!$I$9)) | AD9: =IF(LISTES!$I$10="",0,SUMIFS(SAISIE!$L$2:$L$501,SAISIE!$C$2:$C$501,LISTES!$I$10)) | AE9: =IF(LISTES!$I$11="",0,SUMIFS(SAISIE!$L$2:$L$501,SAISIE!$C$2:$C$501,LISTES!$I$11))
A10: =LISTES!$A$10 | B10: =IF(LISTES!$E$2="",0,SUMIFS(SAISIE!$M$2:$M$501,SAISIE!$C$2:$C$501,LISTES!$E$2)) | C10: =IF(LISTES!$E$3="",0,SUMIFS(SAISIE!$M$2:$M$501,SAISIE!$C$2:$C$501,LISTES!$E$3)) | D10: =IF(LISTES!$E$4="",0,SUMIFS(SAISIE!$M$2:$M$501,SAISIE!$C$2:$C$501,LISTES!$E$4)) | E10: =IF(LISTES!$E$5="",0,SUMIFS(SAISIE!$M$2:$M$501,SAISIE!$C$2:$C$501,LISTES!$E$5)) | F10: =IF(LISTES!$E$6="",0,SUMIFS(SAISIE!$M$2:$M$501,SAISIE!$C$2:$C$501,LISTES!$E$6)) | G10: =IF(LISTES!$E$7="",0,SUMIFS(SAISIE!$M$2:$M$501,SAISIE!$C$2:$C$501,LISTES!$E$7)) | H10: =IF(LISTES!$E$8="",0,SUMIFS(SAISIE!$M$2:$M$501,SAISIE!$C$2:$C$501,LISTES!$E$8)) | I10: =IF(LISTES!$E$9="",0,SUMIFS(SAISIE!$M$2:$M$501,SAISIE!$C$2:$C$501,LISTES!$E$9)) | J10: =IF(LISTES!$E$10="",0,SUMIFS(SAISIE!$M$2:$M$501,SAISIE!$C$2:$C$501,LISTES!$E$10)) | K10: =IF(LISTES!$E$11="",0,SUMIFS(SAISIE!$M$2:$M$501,SAISIE!$C$2:$C$501,LISTES!$E$11)) | L10: =IF(LISTES!$G$2="",0,SUMIFS(SAISIE!$M$2:$M$501,SAISIE!$C$2:$C$501,LISTES!$G$2)) | M10: =IF(LISTES!$G$3="",0,SUMIFS(SAISIE!$M$2:$M$501,SAISIE!$C$2:$C$501,LISTES!$G$3)) | N10: =IF(LISTES!$G$4="",0,SUMIFS(SAISIE!$M$2:$M$501,SAISIE!$C$2:$C$501,LISTES!$G$4)) | O10: =IF(LISTES!$G$5="",0,SUMIFS(SAISIE!$M$2:$M$501,SAISIE!$C$2:$C$501,LISTES!$G$5)) | P10: =IF(LISTES!$G$6="",0,SUMIFS(SAISIE!$M$2:$M$501,SAISIE!$C$2:$C$501,LISTES!$G$6)) | Q10: =IF(LISTES!$G$7="",0,SUMIFS(SAISIE!$M$2:$M$501,SAISIE!$C$2:$C$501,LISTES!$G$7)) | R10: =IF(LISTES!$G$8="",0,SUMIFS(SAISIE!$M$2:$M$501,SAISIE!$C$2:$C$501,LISTES!$G$8)) | S10: =IF(LISTES!$G$9="",0,SUMIFS(SAISIE!$M$2:$M$501,SAISIE!$C$2:$C$501,LISTES!$G$9)) | T10: =IF(LISTES!$G$10="",0,SUMIFS(SAISIE!$M$2:$M$501,SAISIE!$C$2:$C$501,LISTES!$G$10)) | U10: =IF(LISTES!$G$11="",0,SUMIFS(SAISIE!$M$2:$M$501,SAISIE!$C$2:$C$501,LISTES!$G$11)) | V10: =IF(LISTES!$I$2="",0,SUMIFS(SAISIE!$M$2:$M$501,SAISIE!$C$2:$C$501,LISTES!$I$2)) | W10: =IF(LISTES!$I$3="",0,SUMIFS(SAISIE!$M$2:$M$501,SAISIE!$C$2:$C$501,LISTES!$I$3)) | X10: =IF(LISTES!$I$4="",0,SUMIFS(SAISIE!$M$2:$M$501,SAISIE!$C$2:$C$501,LISTES!$I$4)) | Y10: =IF(LISTES!$I$5="",0,SUMIFS(SAISIE!$M$2:$M$501,SAISIE!$C$2:$C$501,LISTES!$I$5)) | Z10: =IF(LISTES!$I$6="",0,SUMIFS(SAISIE!$M$2:$M$501,SAISIE!$C$2:$C$501,LISTES!$I$6)) | AA10: =IF(LISTES!$I$7="",0,SUMIFS(SAISIE!$M$2:$M$501,SAISIE!$C$2:$C$501,LISTES!$I$7)) | AB10: =IF(LISTES!$I$8="",0,SUMIFS(SAISIE!$M$2:$M$501,SAISIE!$C$2:$C$501,LISTES!$I$8)) | AC10: =IF(LISTES!$I$9="",0,SUMIFS(SAISIE!$M$2:$M$501,SAISIE!$C$2:$C$501,LISTES!$I$9)) | AD10: =IF(LISTES!$I$10="",0,SUMIFS(SAISIE!$M$2:$M$501,SAISIE!$C$2:$C$501,LISTES!$I$10)) | AE10: =IF(LISTES!$I$11="",0,SUMIFS(SAISIE!$M$2:$M$501,SAISIE!$C$2:$C$501,LISTES!$I$11))
